Workbook

Sheet 使用說明
A1: 無紙化及自動化流程｜素材總表
A2: 文創科技股份有限公司 所有人名、金額、廠商皆為範例資料
A4: 工作表 | B4: 用途
A5: 流程1_月結表 | B5: 員工出勤、請假、加班彙總與薪資試算（無數字的欄位自動隱藏，可展開）
A6: 流程1_參數 | B6: 假別（含給薪比例）與加班別倍率、勞健保費率等可調參數
A7: 法規符合性檢核 | B7: 逐項對照勞基法、請假規則、會計與個資等法規，註明本設計對應與需公司決策事項
A8: 流程1_出勤紀錄 | B8: 逐日打卡紀錄（精確到分鐘），自動檢核工時與加班同意
A9: 流程1_請假申請 | B9: 請假登記；主管確認、職務代理人為建議、急病可代辦，不以未指定代理人拒絕給假
A10: 流程1_特休與請假查詢 | B10: 曆年制特休按比例、遞延與年度／離職結算，並彙總各假別累計；為員工自助查詢系統的資料來源
A11: 流程1_薪資明細單 | B11: 依勞基法第23條產出每人薪資明細（可電子提供）
A12: 流程1_傳票彙總 | B12: 由月結表自動彙總薪資傳票借貸金額，供拋轉或手 key 金城
A13: 流程2_報銷申請 | B13: 費用報銷申請單欄位（Google 表單／自建平台對應資料表）
A14: 填寫規則 | B14: 報銷可選會計科目（下拉選單來源）與全部科目對照
A15: 淡黃色底的儲存格＝需要人工輸入；其餘為公式或固定欄位，請勿覆蓋。 | B15: 銷項發票登記；與「流程2_報銷申請」的進項一起產生營業稅進銷項申報檔
... A20: 表單欄位設計 | B20: Google 表單／自建平台的題目與欄位清單

Sheet 法規符合性檢核
A1: 法規符合性檢核（無紙化及自動化流程）
A2: 查詢日期：2026-10-20；依公開法規與主管機關說明整理，非法律意見，正式適用請與勞資、會計專業人員確認；狀態「需公司決策」表示需公司制度或專業確認，非 Excel 可單獨解決
A4: 項次 | B4: 領域 | C4: 法規依據 | D4: 要求重點 | E4: 本設計對應 | F4: 狀態
A5: 1 | B5: 工資給付 | C5: 勞基法第22條、第23條；施行細則第14-1條 | D5: 工資全額直接給付；發薪時提供各項目計算方式明細，可電子提供，不得要求申請核可或簽名後收回 | E5: 新增「流程1_薪資明細單」，由月結表自動帶出總額、各項目、扣除項目與實發金額 | F5: 已納入
A6: 2 | B6: 工資清冊 | C6: 勞基法第23條第2項 | D6: 置備工資清冊（發放工資、計算方式明細、工資總額），保存5年 | E6: 月結表即工資清冊，歸檔PDF保存；保存期限由公司執行 | F6: 已納入
A7: 3 | B7: 出勤紀錄 | C7: 勞基法第30條第5、6項 | D7: 逐日記載出勤情形至分鐘，保存5年；不得以表定時間代替；勞工得申請副本 | E7: 新增「流程1_出勤紀錄」，以打卡鐘實際時間逐日登錄；打卡資料需自行匯入 | F7: 已納入
A8: 4 | B8: 工時與加班 | C8: 勞基法第30條、第32條、第36條 | D8: 每日工作含加班不得逾12小時；每月延長工時上限（46小時，經工會或勞資會議同意可放寬）；加班須勞工同意；例假日出勤限天災、事變、突發事件 | E8: 出勤紀錄檢核欄提示逾12小時、未取得加班同意、例假日出勤；月結表提示逾46小時 | F8: 已納入
A9: 5 | B9: 加班費 | C9: 勞基法第24條、第39條 | D9: 平日延長前2小時加給1/3以上，再延長2小時加給2/3以上；休息日、國定假日、例假日依規定計算；不可使用1.33、1.66倍 | E9: 「流程1_參數」列出各時段倍率（1.34／1.67／2.67／加發一日工資） | F9: 已納入
A10: 6 | B10: 加班補休 | C10: 勞基法第32條之1 | D10: 勞工選擇補休須經雇主同意並依工作時數計算；期限屆滿或契約終止未補休須折發工資 | E10: 本設計以給付加班費為主，未建補休欄位 | F10: 需公司決策
A11: 7 | B11: 請假 | C11: 勞基法第43條；勞工請假規則第10條 | D11: 勞工有正當事由即得請假；雇主得要求證明文件，無准駁權；急病或緊急事故得委託他人代辦 | E11: 請假申請以「主管確認」取代核准／退回；需補證明僅用於補件；新增急病代辦欄；職務代理人僅為建議，不作為給假條件 | F11: 已納入
A12: 8 | B12: 假別與給薪 | C12: 勞工請假規則；性別平等工作法 | D12: 各假別日數與給薪比例；自115/1/1起普通傷病假10日內不得不利處分，且不得因此扣發全勤獎金 | E12: 「流程1_參數」列14種假別；公司若有全勤獎金，規則須與此一致 | F12: 需人資確認
A13: 9 | B13: 特別休假 | C13: 勞基法第38條；施行細則第24條、第24條之1 | D13: 特休由勞工排定；公司採曆年制按比例換算；年度終結或離職未休日數須折發工資（年度終結後30日內、離職時結清），經勞工提出並經同意可遞延一次；一日工資以年度終結或離職前最近一個月工資÷30；每年書面（含電子）通知可休日數與未休工資並記載於工資清冊 | E13: 「流程1_特休與請假查詢」依曆年制按比例計算、處理遞延與年度／離職結算，自動帶入月結表「未休假薪資」；員工查詢系統顯示並可下載年度統計（含特休結算） | F13: 已納入
A14: 10 | B14: 年度所得申報 | C14: 所得稅法第88條、第92條；全民健保法補充保險費規定 | D14: 扣繳稅款次月10日前繳納；次年1月31日前申報各類所得扣繳憑單（遇連假順延）、2月10日前填發；補充保費依健保署規定扣取、繳納與申報 | E14: 「6_申報檔產生」的 tax_export.py 依官方格式產生各類所得申報檔（UTF-8，U8）與補充保費明細申報檔（CSV），可直接匯入申報系統；annual.py 供核對；員工可下載年度統計供報稅參考 | F14: 需專業確認
A15: 11 | B15: 遲到扣款 | C15: 勞基法第22條 | D15: 扣款不得超過實際工資 | E15: 以分鐘折算時薪扣款，基礎未高於實際工資 | F15: 已納入
A16: 12 | B16: 勞健保與勞退 | C16: 勞工保險條例；全民健保法；勞工退休金條例 | D16: 依實際薪資所屬級距投保、提繳，不得低報；雇主提繳率不得低於6% | E16: 月結表以手動輸入各級距薪資，費率與提繳率在參數表；級距每年需更新 | F16: 已納入
... A22: 18 | B22: 保存年限彙總 | C22: 勞基法第23條、第30條；商業會計法第38條 | D22: 工資清冊5年、出勤紀錄5年、會計憑證5年、帳簿10年 | E22: 各項歸檔資料依此年限保存，屆期處理前先確認個資刪除義務與其他保存需求 | F22: 需公司決策

Sheet 流程1_月結表
A1: 員工出勤與薪資月結表
A2: 淡黃＝輸入；其餘為公式。無數字的欄位已隱藏（欄位上方的＋或數字「1」「2」可展開／收合）。個資欄位請限制存取權限
A5: 項次 | B5: 員工編號 | C5: 姓名 | D5: 身分證字號 | E5: 撫養親屬 | F5: 到職日 | G5: 本薪 | H5: 伙食費 | I5: 計薪日/時 | J5: 病假 | K5: 遲到(分) | L5: 事假 | M5: 生理假 | N5: 家庭照顧假 | O5: 安胎休養假 | P5: 婚假 | Q5: 喪假 | R5: 產假 | S5: 產檢假 | T5: 陪產檢及陪產假 | U5: 公傷病假 | V5: 公假 | W5: 特別休假 | X5: 育嬰留職停薪 | Y5: 請假日數 | Z5: 平日加班 第1-2小時 | AA5: 平日加班 第3-4小時 | AB5: 休息日 前2小時 | AC5: 休息日 第3-8小時 | AD5: 休息日 第9-12小時 | AE5: 國定假日出勤(日) | AF5: 國定假日加班 第9-10小時 | AG5: 國定假日加班 第11-12小時 | AH5: 例假日出勤(日) | AI5: 例假日加班 超過8小時 | AJ5: 加班時數合計 | AK5: 加班時數檢核 | AL5: 本薪 | AM5: 績效獎金 | AN5: 病假扣款 | AO5: 遲到扣款 | AP5: 事假扣款 | AQ5: 加班費 | AR5: 應稅所得 | AS5: 伙食費 | AT5: 應計薪資 | AU5: 薪資扣繳 | AV5: 獎金扣繳 | AW5: 勞保薪資 | AX5: 勞保代扣 | AY5: 勞保公司負擔 | AZ5: 勞保補〈退〉 | BA5: 勞保費 | BB5: 勞退準備金 | BC5: 勞退薪資 | BD5: 雇主提繳率 | BE5: 雇主提撥 | BF5: 勞退自願提繳率 | BG5: 勞退代扣 | BH5: 健保薪資 | BI5: 健保代扣 | BJ5: 健保補〈退〉 | BK5: 健保公司負擔 | BL5: 健保費 | BM5: 其他代扣款 | BN5: 補充保險費代扣 | BO5: 資遣費 | BP5: 未休假薪資 | BQ5: 其他(兼職) | BR5: 薪資總計 | BS5: 銀行帳戶--中國信託 | BT5: 加項金額 | BU5: 減項金額 | BV5: 實領金額 | BW5: 備註
A6: 1 | B6: E001 | C6: 範例員工A | D6: A1XXXXXXXX | E6: 1 | F6: 2015-03-01 | G6: 60000 | H6: 3000 | I6: 30 | J6: 1 | K6: 30 | L6: 0 | M6: 0 | N6: 0 | O6: 0 | P6: 0 | Q6: 0 | R6: 0 | S6: 0 | T6: 0 | U6: 0 | V6: 0 | W6: 0 | X6: 0 | Y6: =J6+L6+M6+N6+O6+P6+Q6+R6+S6+T6+U6+V6+W6+X6 -> 1 | Z6: 2 | AA6: 2 | AB6: 0 | AC6: 0 | AD6: 0 | AE6: 0 | AF6: 0 | AG6: 0 | AH6: 0 | AI6: 0 | AJ6: =Z6+AA6+AB6+AC6+AD6+AF6+AG6+AI6 -> 4 | AK6: =IF(AJ6>46,"逾46小時","") | AL6: =ROUND(G6/流程1_參數!$C$5*I6,0) -> 60000 | AM6: 0 | AN6: =ROUND(G6/流程1_參數!$C$5*(J6*流程1_參數!$D$21+M6*流程1_參數!$D$24+O6*流程1_參數!$D$25),0) -> 1000 | AO6: =ROUND(G6/流程1_參數!$C$5/流程1_參數!$C$6/60*K6*流程1_參數!$C$8,0) -> 125 | AP6: =ROUND(G6/流程1_參數!$C$5*(L6*流程1_參數!$D$22+N6*流程1_參數!$D$23+X6*流程1_參數!$D$34),0) -> 0 | AQ6: =ROUND((G6+H6*流程1_參數!$C$7)/流程1_參數!$C$5/流程1_參數!$C$6*(Z6*流程1_參數!$D$38+AA6*流程1_參數!$D$39+AB6*流程1_參數!$D$40+AC6*流程1_參數!$D$41+AD6*流程1_參數!$D$42+AF6*流程1_參數!$D$44+AG6*流程1_參數!$D$45+AI6*流程1_參數!$D$47)+(G6+H6*流程1_參數!$C$7)/流程1_參數!$C$5*(AE6*流程1_參數!$D$43+AH6*流程1_參數!$D$46),0) -> 1580 | AR6: =AL6+AM6+AQ6-AN6-AO6-AP6 -> 60455 | AS6: =H6 -> 3000 | AT6: =AR6+AS6 -> 63455 | AU6: 0 | AV6: 0 | AW6: 45800 | AX6: =ROUND(AW6*流程1_參數!$C$9*流程1_參數!$C$10,0) -> 1145 | AY6: =ROUND(AW6*流程1_參數!$C$9*流程1_參數!$C$11,0) -> 4007 | AZ6: 0 | BA6: =AX6+AY6+AZ6 -> 5152 | BB6: =BE6+BG6 -> 3828 | BC6: 63800 | BD6: =流程1_參數!$C$17 -> 0.06 | BE6: =ROUND(BC6*BD6,0) -> 3828 | BF6: 0 | BG6: =ROUND(BC6*BF6,0) -> 0 | BH6: 63800 | BI6: =ROUND(BH6*流程1_參數!$C$12*流程1_參數!$C$13*(1+MIN(E6,流程1_參數!$C$15)),0) -> 1979 | BJ6: 0 | BK6: =ROUND(BH6*流程1_參數!$C$12*流程1_參數!$C$14*流程1_參數!$C$16,0) -> 3087 | BL6: =BI6+BJ6+BK6 -> 5066 | BM6: 0 | BN6: 0 | BO6: 0 | BP6: =IFERROR(INDEX(流程1_特休與請假查詢!$Q$5:$Q$34,MATCH(B6,流程1_特休與請假查詢!$A$5:$A$34,0)),0) -> 0 | BQ6: 0 | BR6: =AT6+BO6+BP6+BQ6 -> 63455 | BS6: （範例）000-000-000000 | BT6: =BR6 -> 63455 | BU6: =AU6+AV6+AX6+AZ6+BG6+BI6+BJ6+BM6+BN6 -> 3124 | BV6: =BT6-BU6 -> 60331
A7: 2 | B7: E002 | C7: 範例員工B | D7: B2XXXXXXXX | E7: 0 | F7: 2019-07-15 | G7: 65000 | H7: 3000 | I7: 30 | J7: 0 | K7: 0 | L7: 1 | M7: 0 | N7: 0 | O7: 0 | P7: 0 | Q7: 0 | R7: 0 | S7: 0 | T7: 0 | U7: 0 | V7: 0 | W7: 1 | X7: 0 | Y7: =J7+L7+M7+N7+O7+P7+Q7+R7+S7+T7+U7+V7+W7+X7 -> 2 | Z7: 0 | AA7: 0 | AB7: 2 | AC7: 6 | AD7: 0 | AE7: 1 | AF7: 0 | AG7: 0 | AH7: 0 | AI7: 0 | AJ7: =Z7+AA7+AB7+AC7+AD7+AF7+AG7+AI7 -> 8 | AK7: =IF(AJ7>46,"逾46小時","") | AL7: =ROUND(G7/流程1_參數!$C$5*I7,0) -> 65000 | AM7: 0 | AN7: =ROUND(G7/流程1_參數!$C$5*(J7*流程1_參數!$D$21+M7*流程1_參數!$D$24+O7*流程1_參數!$D$25),0) -> 0 | AO7: =ROUND(G7/流程1_參數!$C$5/流程1_參數!$C$6/60*K7*流程1_參數!$C$8,0) -> 0 | AP7: =ROUND(G7/流程1_參數!$C$5*(L7*流程1_參數!$D$22+N7*流程1_參數!$D$23+X7*流程1_參數!$D$34),0) -> 2167 | AQ7: =ROUND((G7+H7*流程1_參數!$C$7)/流程1_參數!$C$5/流程1_參數!$C$6*(Z7*流程1_參數!$D$38+AA7*流程1_參數!$D$39+AB7*流程1_參數!$D$40+AC7*流程1_參數!$D$41+AD7*流程1_參數!$D$42+AF7*流程1_參數!$D$44+AG7*流程1_參數!$D$45+AI7*流程1_參數!$D$47)+(G7+H7*流程1_參數!$C$7)/流程1_參數!$C$5*(AE7*流程1_參數!$D$43+AH7*流程1_參數!$D$46),0) -> 5865 | AR7: =AL7+AM7+AQ7-AN7-AO7-AP7 -> 68698 | AS7: =H7 -> 3000 | AT7: =AR7+AS7 -> 71698 | AU7: 0 | AV7: 0 | AW7: 45800 | AX7: =ROUND(AW7*流程1_參數!$C$9*流程1_參數!$C$10,0) -> 1145 | AY7: =ROUND(AW7*流程1_參數!$C$9*流程1_參數!$C$11,0) -> 4007 | AZ7: 0 | BA7: =AX7+AY7+AZ7 -> 5152 | BB7: =BE7+BG7 -> 6282 | BC7: 69800 | BD7: =流程1_參數!$C$17 -> 0.06 | BE7: =ROUND(BC7*BD7,0) -> 4188 | BF7: 0.03 | BG7: =ROUND(BC7*BF7,0) -> 2094 | BH7: 69800 | BI7: =ROUND(BH7*流程1_參數!$C$12*流程1_參數!$C$13*(1+MIN(E7,流程1_參數!$C$15)),0) -> 1083 | BJ7: 0 | BK7: =ROUND(BH7*流程1_參數!$C$12*流程1_參數!$C$14*流程1_參數!$C$16,0) -> 3378 | BL7: =BI7+BJ7+BK7 -> 4461 | BM7: 0 | BN7: 0 | BO7: 0 | BP7: =IFERROR(INDEX(流程1_特休與請假查詢!$Q$5:$Q$34,MATCH(B7,流程1_特休與請假查詢!$A$5:$A$34,0)),0) -> 0 | BQ7: 0 | BR7: =AT7+BO7+BP7+BQ7 -> 71698 | BS7: （範例）000-000-000000 | BT7: =BR7 -> 71698 | BU7: =AU7+AV7+AX7+AZ7+BG7+BI7+BJ7+BM7+BN7 -> 4322 | BV7: =BT7-BU7 -> 67376
A8: 3 | B8: E003 | C8: 範例員工C | D8: C3XXXXXXXX | E8: 2 | F8: 2021-01-04 | G8: 42000 | H8: 3000 | I8: 30 | J8: 0 | K8: 0 | L8: 0 | M8: 0 | N8: 0 | O8: 0 | P8: 0 | Q8: 0 | R8: 0 | S8: 0 | T8: 0 | U8: 0 | V8: 0 | W8: 0 | X8: 0 | Y8: =J8+L8+M8+N8+O8+P8+Q8+R8+S8+T8+U8+V8+W8+X8 -> 0 | Z8: 0 | AA8: 0 | AB8: 0 | AC8: 0 | AD8: 0 | AE8: 0 | AF8: 0 | AG8: 0 | AH8: 0 | AI8: 0 | AJ8: =Z8+AA8+AB8+AC8+AD8+AF8+AG8+AI8 -> 0 | AK8: =IF(AJ8>46,"逾46小時","") | AL8: =ROUND(G8/流程1_參數!$C$5*I8,0) -> 42000 | AM8: 0 | AN8: =ROUND(G8/流程1_參數!$C$5*(J8*流程1_參數!$D$21+M8*流程1_參數!$D$24+O8*流程1_參數!$D$25),0) -> 0 | AO8: =ROUND(G8/流程1_參數!$C$5/流程1_參數!$C$6/60*K8*流程1_參數!$C$8,0) -> 0 | AP8: =ROUND(G8/流程1_參數!$C$5*(L8*流程1_參數!$D$22+N8*流程1_參數!$D$23+X8*流程1_參數!$D$34),0) -> 0 | AQ8: =ROUND((G8+H8*流程1_參數!$C$7)/流程1_參數!$C$5/流程1_參數!$C$6*(Z8*流程1_參數!$D$38+AA8*流程1_參數!$D$39+AB8*流程1_參數!$D$40+AC8*流程1_參數!$D$41+AD8*流程1_參數!$D$42+AF8*流程1_參數!$D$44+AG8*流程1_參數!$D$45+AI8*流程1_參數!$D$47)+(G8+H8*流程1_參數!$C$7)/流程1_參數!$C$5*(AE8*流程1_參數!$D$43+AH8*流程1_參數!$D$46),0) -> 0 | AR8: =AL8+AM8+AQ8-AN8-AO8-AP8 -> 42000 | AS8: =H8 -> 3000 | AT8: =AR8+AS8 -> 45000 | AU8: 0 | AV8: 0 | AW8: 45800 | AX8: =ROUND(AW8*流程1_參數!$C$9*流程1_參數!$C$10,0) -> 1145 | AY8: =ROUND(AW8*流程1_參數!$C$9*流程1_參數!$C$11,0) -> 4007 | AZ8: 0 | BA8: =AX8+AY8+AZ8 -> 5152 | BB8: =BE8+BG8 -> 2748 | BC8: 45800 | BD8: =流程1_參數!$C$17 -> 0.06 | BE8: =ROUND(BC8*BD8,0) -> 2748 | BF8: 0 | BG8: =ROUND(BC8*BF8,0) -> 0 | BH8: 45800 | BI8: =ROUND(BH8*流程1_參數!$C$12*流程1_參數!$C$13*(1+MIN(E8,流程1_參數!$C$15)),0) -> 2131 | BJ8: 0 | BK8: =ROUND(BH8*流程1_參數!$C$12*流程1_參數!$C$14*流程1_參數!$C$16,0) -> 2216 | BL8: =BI8+BJ8+BK8 -> 4347 | BM8: 0 | BN8: 0 | BO8: 0 | BP8: =IFERROR(INDEX(流程1_特休與請假查詢!$Q$5:$Q$34,MATCH(B8,流程1_特休與請假查詢!$A$5:$A$34,0)),0) -> 0 | BQ8: 0 | BR8: =AT8+BO8+BP8+BQ8 -> 45000 | BS8: （範例）000-000-000000 | BT8: =BR8 -> 45000 | BU8: =AU8+AV8+AX8+AZ8+BG8+BI8+BJ8+BM8+BN8 -> 3276 | BV8: =BT8-BU8 -> 41724
A9: 合計 | G9: =SUM(G6:G8) -> 167000 | H9: =SUM(H6:H8) -> 9000 | Y9: =SUM(Y6:Y8) -> 3 | AJ9: =SUM(AJ6:AJ8) -> 12 | AL9: =SUM(AL6:AL8) -> 167000 | AM9: =SUM(AM6:AM8) -> 0 | AN9: =SUM(AN6:AN8) -> 1000 | AO9: =SUM(AO6:AO8) -> 125 | AP9: =SUM(AP6:AP8) -> 2167 | AQ9: =SUM(AQ6:AQ8) -> 7445 | AR9: =SUM(AR6:AR8) -> 171153 | AS9: =SUM(AS6:AS8) -> 9000 | ... AV9: =SUM(AV6:AV8) -> 0 | AX9: =SUM(AX6:AX8) -> 3435 | AY9: =SUM(AY6:AY8) -> 12021 | AZ9: =SUM(AZ6:AZ8) -> 0 | BA9: =SUM(BA6:BA8) -> 15456 | BB9: =SUM(BB6:BB8) -> 12858 | BE9: =SUM(BE6:BE8) -> 10764 | BG9: =SUM(BG6:BG8) -> 2094 | BI9: =SUM(BI6:BI8) -> 5193 | BJ9: =SUM(BJ6:BJ8) -> 0 | BK9: =SUM(BK6:BK8) -> 8681 | BL9: =SUM(BL6:BL8) -> 13874 | BM9: =SUM(BM6:BM8) -> 0 | BN9: =SUM(BN6:BN8) -> 0 | BO9: =SUM(BO6:BO8) -> 0 | BP9: =SUM(BP6:BP8) -> 0 | ... BR9: =SUM(BR6:BR8) -> 180153 | BT9: =SUM(BT6:BT8) -> 180153 | BU9: =SUM(BU6:BU8) -> 10722 | BV9: =SUM(BV6:BV8) -> 169431
A11: 註：勞健保薪資請依勞保局、健保署最新分級表填入；扣繳稅額依扣繳率標準；勞保費＝代扣＋公司負擔＋補退（政府負擔10%不含）。範例人名、身分證字號、帳號皆為虛構。
A12: 加班費基礎＝（本薪＋經常性給與）÷30÷8；各倍率與假別扣薪比例見「流程1_參數」。

Sheet 流程1_參數
A1: 薪資計算參數（假別與加班別）
A2: 藍字為可修改參數；法規數字依勞動基準法、勞工請假規則、性別平等工作法整理，正式使用前請與人資／會計確認
B4: 參數 | C4: 數值 | D4: 說明／來源
B5: 月薪折算日數 | C5: 30 | D5: 日薪＝月薪÷30
B6: 每日工時(小時) | C6: 8 | D6: 時薪＝日薪÷8（即月薪÷240）
B7: 伙食費納入加班費計算基礎(1=是,0=否) | C7: 1 | D7: 經常性給與屬工資，計算平日每小時工資額應納入；請與人資確認各項津貼性質
B8: 遲到扣薪比例 | C8: 1 | D8: 遲到按分鐘折算時薪扣款；是否扣薪依公司工作規則
B9: 勞保費率 | C9: 0.125 | D9: 115年：普通事故11.5%＋就業保險1%＝12.5%，不含職災保險（全額雇主負擔）
B10: 勞保－員工負擔比例 | C10: 0.2 | D10: 員工20%、雇主70%、政府10%
B11: 勞保－雇主負擔比例 | C11: 0.7
B12: 健保費率 | C12: 0.0517 | D12: 115年維持5.17%
B13: 健保－員工負擔比例 | C13: 0.3 | D13: 員工30%、雇主60%、政府10%
B14: 健保－雇主負擔比例 | C14: 0.6
B15: 健保眷屬計費人數上限 | C15: 3 | D15: 眷屬超過3口以3口計
B16: 健保－雇主負擔人數(含平均眷屬) | C16: 1.56 | D16: 本人＋平均眷屬0.56人
B17: 勞退雇主提繳率 | C17: 0.06 | D17: 雇主提繳率不得低於6%；員工可自願提繳0%～6%
B19: 假別表（影響扣款的假別才會被月結表公式使用；其餘供紀錄與核對）
B20: 假別 | C20: 給薪比例 | D20: 扣薪比例 | E20: 日數上限 | F20: 法源 | G20: 備註
B21: 病假（普通傷病假） | C21: 0.5 | D21: =1-C21 -> 0.5 | E21: 未住院每年30日 | F21: 勞工請假規則 | G21: 半薪；115/1/1起請病假10日內不得不利處分，且不得因此扣發全勤獎金
B22: 事假 | C22: 0 | D22: =1-C22 -> 1 | E22: 每年14日 | F22: 勞工請假規則 | G22: 不給薪
B23: 家庭照顧假 | C23: 0 | D23: =1-C23 -> 1 | E23: 每年7日（併入事假） | F23: 性別平等工作法 | G23: 不給薪，日數併入事假計算
B24: 生理假 | C24: 0.5 | D24: =1-C24 -> 0.5 | E24: 每月1日；全年3日內不併入病假 | F24: 性別平等工作法 | G24: 半薪；超過3日部分併入病假；不得扣全勤
B25: 安胎休養假 | C25: 0.5 | D25: =1-C25 -> 0.5 | E25: 依醫師診斷 | F25: 性別平等工作法 | G25: 併入住院傷病假計算，半薪
B26: 婚假 | C26: 1 | D26: =1-C26 -> 0 | E26: 8日 | F26: 勞工請假規則 | G26: 工資照給
B27: 喪假 | C27: 1 | D27: =1-C27 -> 0 | E27: 3／6／8日（依親屬關係） | F27: 勞工請假規則 | G27: 工資照給；3日：曾祖父母、兄弟姊妹等；6日：祖父母、子女、配偶之父母等；8日：父母、配偶
B28: 產假 | C28: 1 | D28: =1-C28 -> 0 | E28: 8週（流產依週數另計） | F28: 性別平等工作法 | G28: 受僱滿6個月照給，未滿6個月減半
B29: 產檢假 | C29: 1 | D29: =1-C29 -> 0 | E29: 7日 | F29: 性別平等工作法 | G29: 工資照給
B30: 陪產檢及陪產假 | C30: 1 | D30: =1-C30 -> 0 | E30: 7日 | F30: 性別平等工作法 | G30: 工資照給
B31: 公傷病假 | C31: 1 | D31: =1-C31 -> 0 | E31: 依實際需要 | F31: 勞動基準法第59條 | G31: 按原領工資補償，不得扣全勤
B32: 公假 | C32: 1 | D32: =1-C32 -> 0 | E32: 依法令規定 | F32: 勞工請假規則 | G32: 工資照給
... B34: 育嬰留職停薪 | C34: 0 | D34: =1-C34 -> 1 | E34: 依申請 | F34: 性別平等工作法 | G34: 不給薪（可申請勞保育嬰留職停薪津貼）
B36: 加班別表（勞動基準法第24條、第32條、第36條、第39條）
B37: 加班別 | C37: 時段 | D37: 倍率 | E37: 計算方式 | F37: 備註
B38: 平日延長工時 | C38: 第1–2小時 | D38: 1.34 | E38: 時數×時薪×倍率 | F38: 加給1/3以上，不可用1.33
B39: 平日延長工時 | C39: 第3–4小時 | D39: 1.67 | E39: 時數×時薪×倍率 | F39: 再延長2小時內加給2/3以上，不可用1.66
B40: 休息日出勤 | C40: 前2小時 | D40: 1.34 | E40: 時數×時薪×倍率 | F40: 需勞工同意；核實計算時數
B41: 休息日出勤 | C41: 第3–8小時 | D41: 1.67 | E41: 時數×時薪×倍率
B42: 休息日出勤 | C42: 第9–12小時 | D42: 2.67 | E42: 時數×時薪×倍率
B43: 國定假日（含經同意的特休日）出勤 | C43: 8小時內 | D43: 1 | E43: 日數×日薪（加發一日工資） | F43: 月薪制當日工資已含，出勤另加發一日工資，不足8小時亦同
B44: 國定假日延長工時 | C44: 第9–10小時 | D44: 1.34 | E44: 時數×時薪×倍率
...

Sheet 流程1_出勤紀錄
A1: 員工出勤紀錄（逐日、精確到分鐘）
A2: 依勞基法第30條：逐日記載出勤情形至分鐘，保存5年；須以實際打卡時間填寫，不得以表定時間代替；勞工得申請副本
A4: 日期 | B4: 員工編號 | C4: 姓名 | D4: 日別 | E4: 上班打卡 | F4: 下班打卡 | G4: 休息(分) | H4: 工作時數 | I4: 加班時數 | J4: 加班同意 | K4: 檢核 | L4: 備註 | M4: 請假別（請假日填）
A5: 46300 | B5: E001 | C5: 範例員工A | D5: 平日 | E5: 0.375 | F5: 0.91666667 | G5: 60 | H5: =IF(OR(E5="",F5=""),"",ROUND(((F5-E5)*1440-G5)/60,2)) -> 12 | I5: =IF(H5="","",IF(D5="平日",MAX(0,H5-8),IF(OR(D5="休息日",D5="例假日",D5="國定假日",D5="特休日"),H5,0))) -> 4 | J5: 是 | K5: =IF(H5="","",IF(H5>12,"逾12小時",IF(D5="例假日","例假日出勤僅限天災、事變、突發事件",IF(AND(I5>0,J5<>"是"),"未取得加班同意",""))))
A6: 46301 | B6: E001 | C6: 範例員工A | D6: 平日 | E6: 0.375 | F6: 0.75 | G6: 60 | H6: =IF(OR(E6="",F6=""),"",ROUND(((F6-E6)*1440-G6)/60,2)) -> 8 | I6: =IF(H6="","",IF(D6="平日",MAX(0,H6-8),IF(OR(D6="休息日",D6="例假日",D6="國定假日",D6="特休日"),H6,0))) -> 0 | J6: 否 | K6: =IF(H6="","",IF(H6>12,"逾12小時",IF(D6="例假日","例假日出勤僅限天災、事變、突發事件",IF(AND(I6>0,J6<>"是"),"未取得加班同意",""))))
A7: 46302 | B7: E001 | C7: 範例員工A | D7: 平日 | E7: 0.39583333 | F7: 0.77083333 | G7: 60 | H7: =IF(OR(E7="",F7=""),"",ROUND(((F7-E7)*1440-G7)/60,2)) -> 8 | I7: =IF(H7="","",IF(D7="平日",MAX(0,H7-8),IF(OR(D7="休息日",D7="例假日",D7="國定假日",D7="特休日"),H7,0))) -> 0 | J7: 否 | K7: =IF(H7="","",IF(H7>12,"逾12小時",IF(D7="例假日","例假日出勤僅限天災、事變、突發事件",IF(AND(I7>0,J7<>"是"),"未取得加班同意",""))))
A8: 46312 | B8: E002 | C8: 範例員工B | D8: 休息日 | E8: 0.375 | F8: 0.75 | G8: 60 | H8: =IF(OR(E8="",F8=""),"",ROUND(((F8-E8)*1440-G8)/60,2)) -> 8 | I8: =IF(H8="","",IF(D8="平日",MAX(0,H8-8),IF(OR(D8="休息日",D8="例假日",D8="國定假日",D8="特休日"),H8,0))) -> 8 | J8: 是 | K8: =IF(H8="","",IF(H8>12,"逾12小時",IF(D8="例假日","例假日出勤僅限天災、事變、突發事件",IF(AND(I8>0,J8<>"是"),"未取得加班同意",""))))
H9: =IF(OR(E9="",F9=""),"",ROUND(((F9-E9)*1440-G9)/60,2)) | I9: =IF(H9="","",IF(D9="平日",MAX(0,H9-8),IF(OR(D9="休息日",D9="例假日",D9="國定假日",D9="特休日"),H9,0))) | K9: =IF(H9="","",IF(H9>12,"逾12小時",IF(D9="例假日","例假日出勤僅限天災、事變、突發事件",IF(AND(I9>0,J9<>"是"),"未取得加班同意",""))))
H10: =IF(OR(E10="",F10=""),"",ROUND(((F10-E10)*1440-G10)/60,2)) | I10: =IF(H10="","",IF(D10="平日",MAX(0,H10-8),IF(OR(D10="休息日",D10="例假日",D10="國定假日",D10="特休日"),H10,0))) | K10: =IF(H10="","",IF(H10>12,"逾12小時",IF(D10="例假日","例假日出勤僅限天災、事變、突發事件",IF(AND(I10>0,J10<>"是"),"未取得加班同意",""))))
H11: =IF(OR(E11="",F11=""),"",ROUND(((F11-E11)*1440-G11)/60,2)) | I11: =IF(H11="","",IF(D11="平日",MAX(0,H11-8),IF(OR(D11="休息日",D11="例假日",D11="國定假日",D11="特休日"),H11,0))) | K11: =IF(H11="","",IF(H11>12,"逾12小時",IF(D11="例假日","例假日出勤僅限天災、事變、突發事件",IF(AND(I11>0,J11<>"是"),"未取得加班同意",""))))
H12: =IF(OR(E12="",F12=""),"",ROUND(((F12-E12)*1440-G12)/60,2)) | I12: =IF(H12="","",IF(D12="平日",MAX(0,H12-8),IF(OR(D12="休息日",D12="例假日",D12="國定假日",D12="特休日"),H12,0))) | K12: =IF(H12="","",IF(H12>12,"逾12小時",IF(D12="例假日","例假日出勤僅限天災、事變、突發事件",IF(AND(I12>0,J12<>"是"),"未取得加班同意",""))))
H13: =IF(OR(E13="",F13=""),"",ROUND(((F13-E13)*1440-G13)/60,2)) | I13: =IF(H13="","",IF(D13="平日",MAX(0,H13-8),IF(OR(D13="休息日",D13="例假日",D13="國定假日",D13="特休日"),H13,0))) | K13: =IF(H13="","",IF(H13>12,"逾12小時",IF(D13="例假日","例假日出勤僅限天災、事變、突發事件",IF(AND(I13>0,J13<>"是"),"未取得加班同意",""))))
H14: =IF(OR(E14="",F14=""),"",ROUND(((F14-E14)*1440-G14)/60,2)) | I14: =IF(H14="","",IF(D14="平日",MAX(0,H14-8),IF(OR(D14="休息日",D14="例假日",D14="國定假日",D14="特休日"),H14,0))) | K14: =IF(H14="","",IF(H14>12,"逾12小時",IF(D14="例假日","例假日出勤僅限天災、事變、突發事件",IF(AND(I14>0,J14<>"是"),"未取得加班同意",""))))
H15: =IF(OR(E15="",F15=""),"",ROUND(((F15-E15)*1440-G15)/60,2)) | I15: =IF(H15="","",IF(D15="平日",MAX(0,H15-8),IF(OR(D15="休息日",D15="例假日",D15="國定假日",D15="特休日"),H15,0))) | K15: =IF(H15="","",IF(H15>12,"逾12小時",IF(D15="例假日","例假日出勤僅限天災、事變、突發事件",IF(AND(I15>0,J15<>"是"),"未取得加班同意",""))))
H16: =IF(OR(E16="",F16=""),"",ROUND(((F16-E16)*1440-G16)/60,2)) | I16: =IF(H16="","",IF(D16="平日",MAX(0,H16-8),IF(OR(D16="休息日",D16="例假日",D16="國定假日",D16="特休日"),H16,0))) | K16: =IF(H16="","",IF(H16>12,"逾12小時",IF(D16="例假日","例假日出勤僅限天災、事變、突發事件",IF(AND(I16>0,J16<>"是"),"未取得加班同意",""))))
H17: =IF(OR(E17="",F17=""),"",ROUND(((F17-E17)*1440-G17)/60,2)) | I17: =IF(H17="","",IF(D17="平日",MAX(0,H17-8),IF(OR(D17="休息日",D17="例假日",D17="國定假日",D17="特休日"),H17,0))) | K17: =IF(H17="","",IF(H17>12,"逾12小時",IF(D17="例假日","例假日出勤僅限天災、事變、突發事件",IF(AND(I17>0,J17<>"是"),"未取得加班同意",""))))
H18: =IF(OR(E18="",F18=""),"",ROUND(((F18-E18)*1440-G18)/60,2)) | I18: =IF(H18="","",IF(D18="平日",MAX(0,H18-8),IF(OR(D18="休息日",D18="例假日",D18="國定假日",D18="特休日"),H18,0))) | K18: =IF(H18="","",IF(H18>12,"逾12小時",IF(D18="例假日","例假日出勤僅限天災、事變、突發事件",IF(AND(I18>0,J18<>"是"),"未取得加班同意",""))))
H19: =IF(OR(E19="",F19=""),"",ROUND(((F19-E19)*1440-G19)/60,2)) | I19: =IF(H19="","",IF(D19="平日",MAX(0,H19-8),IF(OR(D19="休息日",D19="例假日",D19="國定假日",D19="特休日"),H19,0))) | K19: =IF(H19="","",IF(H19>12,"逾12小時",IF(D19="例假日","例假日出勤僅限天災、事變、突發事件",IF(AND(I19>0,J19<>"是"),"未取得加班同意",""))))
H20: =IF(OR(E20="",F20=""),"",ROUND(((F20-E20)*1440-G20)/60,2)) | I20: =IF(H20="","",IF(D20="平日",MAX(0,H20-8),IF(OR(D20="休息日",D20="例假日",D20="國定假日",D20="特休日"),H20,0))) | K20: =IF(H20="","",IF(H20>12,"逾12小時",IF(D20="例假日","例假日出勤僅限天災、事變、突發事件",IF(AND(I20>0,J20<>"是"),"未取得加班同意",""))))
... H154: =IF(OR(E154="",F154=""),"",ROUND(((F154-E154)*1440-G154)/60,2)) | I154: =IF(H154="","",IF(D154="平日",MAX(0,H154-8),IF(OR(D154="休息日",D154="例假日",D154="國定假日",D154="特休日"),H154,0))) | K154: =IF(H154="","",IF(H154>12,"逾12小時",IF(D154="例假日","例假日出勤僅限天災、事變、突發事件",IF(AND(I154>0,J154<>"是"),"未取得加班同意",""))))
A156: 範例僅示意，未與月結表逐筆對應；打卡鐘資料可匯出後貼入。加班需事前取得勞工同意；每日工作（含加班）不得逾12小時，每月延長工時另有上限。

Sheet 流程1_請假申請
A1: 請假申請登記
A2: 勞工有正當事由即得請假（勞基法第43條）；主管為「確認」而非核准；職務代理人為內部工作安排，非准假條件；急病或緊急事故得委託他人代辦（勞工請假規則第10條）
T3: 員工名單（新增員工請在此補上；證號別 0＝本國個人、3＝居住滿183天之外僑；戶籍地址供所得申報檔使用）
A4: 申請編號 | B4: 公司別 | C4: 申請日期 | D4: 申請人 | E4: 部門 | F4: 假別 | G4: 起始日期 | H4: 結束日期 | I4: 請假日數 | J4: 事由 | K4: 職務代理人 | L4: 代理人確認 | M4: 主管確認 | N4: 證明文件 | O4: 急病／緊急事故代辦 | P4: 代辦人 | Q4: 備註 | R4: 檢核 | T4: 員工編號 | U4: 姓名 | V4: 部門 | W4: 到職日 | X4: 離職日 | Y4: 證號別 | Z4: 戶籍地址
A5: LEAVE-202610-001 | B5: 文創科技股份有限公司 | C5: 46307 | D5: 範例員工A | E5: =IF(D5="","",IFERROR(VLOOKUP(D5,$U$5:$V$34,2,FALSE()),"")) -> 企劃部 | F5: 病假（普通傷病假） | G5: 46309 | H5: 46310 | I5: 2 | J5: 就診休養 | K5: 範例員工C | L5: 已同意 | M5: 已確認 | N5: 就診證明／門診收據 | O5: 否 | R5: =IF(AND(D5="",F5=""),"",IF(AND(O5="是",P5=""),"請填代辦人",IF(K5="","建議指定職務代理人（非法定要件）",IF(K5=D5,"代理人不可為本人",IF(L5<>"已同意","代理人尚未同意（不影響給假）",""))))) | T5: E001 | U5: 範例員工A | V5: 企劃部 | W5: 42064 | Y5: 0 | Z5: 台北市範例區範例路1號
A6: LEAVE-202610-002 | B6: 文創科技股份有限公司 | C6: 46301 | D6: 範例員工B | E6: =IF(D6="","",IFERROR(VLOOKUP(D6,$U$5:$V$34,2,FALSE()),"")) -> 工程部 | F6: 事假 | G6: 46303 | H6: 46303 | I6: 1 | J6: 家中事務 | K6: 範例員工A | L6: 已同意 | M6: 已確認 | O6: 否 | R6: =IF(AND(D6="",F6=""),"",IF(AND(O6="是",P6=""),"請填代辦人",IF(K6="","建議指定職務代理人（非法定要件）",IF(K6=D6,"代理人不可為本人",IF(L6<>"已同意","代理人尚未同意（不影響給假）",""))))) | T6: E002 | U6: 範例員工B | V6: 工程部 | W6: 43661 | Y6: 0 | Z6: 台北市範例區範例路2號
A7: LEAVE-202610-003 | B7: 文創科技股份有限公司 | C7: 46301 | D7: 範例員工B | E7: =IF(D7="","",IFERROR(VLOOKUP(D7,$U$5:$V$34,2,FALSE()),"")) -> 工程部 | F7: 特別休假 | G7: 46304 | H7: 46304 | I7: 1 | J7: 特休 | K7: 範例員工A | L7: 已同意 | M7: 已確認 | O7: 否 | R7: =IF(AND(D7="",F7=""),"",IF(AND(O7="是",P7=""),"請填代辦人",IF(K7="","建議指定職務代理人（非法定要件）",IF(K7=D7,"代理人不可為本人",IF(L7<>"已同意","代理人尚未同意（不影響給假）",""))))) | T7: E003 | U7: 範例員工C | V7: 行政部 | W7: 44200 | Y7: 0 | Z7: 台北市範例區範例路3號
E8: =IF(D8="","",IFERROR(VLOOKUP(D8,$U$5:$V$34,2,FALSE()),"")) | R8: =IF(AND(D8="",F8=""),"",IF(AND(O8="是",P8=""),"請填代辦人",IF(K8="","建議指定職務代理人（非法定要件）",IF(K8=D8,"代理人不可為本人",IF(L8<>"已同意","代理人尚未同意（不影響給假）","")))))
E9: =IF(D9="","",IFERROR(VLOOKUP(D9,$U$5:$V$34,2,FALSE()),"")) | R9: =IF(AND(D9="",F9=""),"",IF(AND(O9="是",P9=""),"請填代辦人",IF(K9="","建議指定職務代理人（非法定要件）",IF(K9=D9,"代理人不可為本人",IF(L9<>"已同意","代理人尚未同意（不影響給假）","")))))
E10: =IF(D10="","",IFERROR(VLOOKUP(D10,$U$5:$V$34,2,FALSE()),"")) | R10: =IF(AND(D10="",F10=""),"",IF(AND(O10="是",P10=""),"請填代辦人",IF(K10="","建議指定職務代理人（非法定要件）",IF(K10=D10,"代理人不可為本人",IF(L10<>"已同意","代理人尚未同意（不影響給假）","")))))
E11: =IF(D11="","",IFERROR(VLOOKUP(D11,$U$5:$V$34,2,FALSE()),"")) | R11: =IF(AND(D11="",F11=""),"",IF(AND(O11="是",P11=""),"請填代辦人",IF(K11="","建議指定職務代理人（非法定要件）",IF(K11=D11,"代理人不可為本人",IF(L11<>"已同意","代理人尚未同意（不影響給假）","")))))
E12: =IF(D12="","",IFERROR(VLOOKUP(D12,$U$5:$V$34,2,FALSE()),"")) | R12: =IF(AND(D12="",F12=""),"",IF(AND(O12="是",P12=""),"請填代辦人",IF(K12="","建議指定職務代理人（非法定要件）",IF(K12=D12,"代理人不可為本人",IF(L12<>"已同意","代理人尚未同意（不影響給假）","")))))
E13: =IF(D13="","",IFERROR(VLOOKUP(D13,$U$5:$V$34,2,FALSE()),"")) | R13: =IF(AND(D13="",F13=""),"",IF(AND(O13="是",P13=""),"請填代辦人",IF(K13="","建議指定職務代理人（非法定要件）",IF(K13=D13,"代理人不可為本人",IF(L13<>"已同意","代理人尚未同意（不影響給假）","")))))
E14: =IF(D14="","",IFERROR(VLOOKUP(D14,$U$5:$V$34,2,FALSE()),"")) | R14: =IF(AND(D14="",F14=""),"",IF(AND(O14="是",P14=""),"請填代辦人",IF(K14="","建議指定職務代理人（非法定要件）",IF(K14=D14,"代理人不可為本人",IF(L14<>"已同意","代理人尚未同意（不影響給假）","")))))
E15: =IF(D15="","",IFERROR(VLOOKUP(D15,$U$5:$V$34,2,FALSE()),"")) | R15: =IF(AND(D15="",F15=""),"",IF(AND(O15="是",P15=""),"請填代辦人",IF(K15="","建議指定職務代理人（非法定要件）",IF(K15=D15,"代理人不可為本人",IF(L15<>"已同意","代理人尚未同意（不影響給假）","")))))
E16: =IF(D16="","",IFERROR(VLOOKUP(D16,$U$5:$V$34,2,FALSE()),"")) | R16: =IF(AND(D16="",F16=""),"",IF(AND(O16="是",P16=""),"請填代辦人",IF(K16="","建議指定職務代理人（非法定要件）",IF(K16=D16,"代理人不可為本人",IF(L16<>"已同意","代理人尚未同意（不影響給假）","")))))
E17: =IF(D17="","",IFERROR(VLOOKUP(D17,$U$5:$V$34,2,FALSE()),"")) | R17: =IF(AND(D17="",F17=""),"",IF(AND(O17="是",P17=""),"請填代辦人",IF(K17="","建議指定職務代理人（非法定要件）",IF(K17=D17,"代理人不可為本人",IF(L17<>"已同意","代理人尚未同意（不影響給假）","")))))
E18: =IF(D18="","",IFERROR(VLOOKUP(D18,$U$5:$V$34,2,FALSE()),"")) | R18: =IF(AND(D18="",F18=""),"",IF(AND(O18="是",P18=""),"請填代辦人",IF(K18="","建議指定職務代理人（非法定要件）",IF(K18=D18,"代理人不可為本人",IF(L18<>"已同意","代理人尚未同意（不影響給假）","")))))
E19: =IF(D19="","",IFERROR(VLOOKUP(D19,$U$5:$V$34,2,FALSE()),"")) | R19: =IF(AND(D19="",F19=""),"",IF(AND(O19="是",P19=""),"請填代辦人",IF(K19="","建議指定職務代理人（非法定要件）",IF(K19=D19,"代理人不可為本人",IF(L19<>"已同意","代理人尚未同意（不影響給假）","")))))
... E64: =IF(D64="","",IFERROR(VLOOKUP(D64,$U$5:$V$34,2,FALSE()),"")) | R64: =IF(AND(D64="",F64=""),"",IF(AND(O64="是",P64=""),"請填代辦人",IF(K64="","建議指定職務代理人（非法定要件）",IF(K64=D64,"代理人不可為本人",IF(L64<>"已同意","代理人尚未同意（不影響給假）","")))))
A66: 說明：「需補證明」僅用於請勞工補件，不等於拒絕給假；生理假等依性別平等工作法不需證明。
A67: 假別與給薪規則見「流程1_參數」；請假日數累計後填入「流程1_月結表」對應假別欄。

Sheet 流程1_特休與請假查詢
A1: 特休餘額、請假累計與未休工資結算（曆年制）
A2: 曆年制：每年1/1–12/31，依年資分段按比例換算；年度終結或離職未休完須折發工資（勞基法第38條第4項、施行細則第24條之1）；僅計入主管已確認的請假
A3: 基準日 | B3: 46326 | D3: 特休進位單位(日) | E3: 0.5 | G3: 結算方式：年度結算請把基準日設為12/31，金額併入次年1月薪資（法定年度終結後30日內發給）；離職請在名單填離職日，基準日設為離職日，離職當日結清。
A4: 員工編號 | B4: 姓名 | C4: 到職日 | D4: 離職日 | E4: 年資(月) | F4: 曆年應有特休(按比例,日) | G4: 上年度遞延至本年(日) | H4: 本年度可休合計 | I4: 已休特休(日) | J4: 剩餘特休(日) | K4: 本年度再遞延至次年(日) | L4: 結算類別 | M4: 遞延日數未休(折發日) | N4: 本年度未休(折發日) | O4: 一日工資(結算基準) | P4: 遞延原年度日薪(空白＝沿用) | Q4: 應折發未休特休工資 | R4: 病假（普通傷病假）（已休日） | S4: 事假（已休日） | T4: 家庭照顧假（已休日） | U4: 生理假（已休日） | V4: 安胎休養假（已休日） | W4: 婚假（已休日） | X4: 喪假（已休日） | Y4: 產假（已休日） | Z4: 產檢假（已休日） | AA4: 陪產檢及陪產假（已休日） | AB4: 公傷病假（已休日） | AC4: 公假（已休日） | AD4: 特別休假（已休日） | AE4: 育嬰留職停薪（已休日） | AF4: 病假剩餘(日,以30日計) | AG4: 事假剩餘(日,以14日計) | AH4: 計算止日 | AI4: 分段點1 | AJ4: 分段點2 | AK4: 年率0 | AL4: 年率1 | AM4: 年率2 | AN4: 未進位應有
A5: =IF(流程1_請假申請!U5="","",流程1_請假申請!T5) -> E001 | B5: =IF(流程1_請假申請!U5="","",流程1_請假申請!U5) -> 範例員工A | C5: =IF(流程1_請假申請!U5="","",流程1_請假申請!W5) -> 42064 | D5: =IF(流程1_請假申請!X5="","",流程1_請假申請!X5) | E5: =IF(C5="","",IF($B$3<C5,0,DATEDIF(C5,$B$3,"m"))) -> 139 | F5: =IF(C5="","",IF(AN5=0,0,CEILING(ROUND(AN5,2),$E$3))) -> 17 | H5: =IF(C5="","",F5+G5) -> 17 | I5: =IF(C5="","",SUMIFS(流程1_請假申請!$I$5:$I$64,流程1_請假申請!$D$5:$D$64,B5,流程1_請假申請!$F$5:$F$64,"特別休假",流程1_請假申請!$M$5:$M$64,"已確認",流程1_請假申請!$G$5:$G$64,">="&DATE(YEAR($B$3),1,1),流程1_請假申請!$G$5:$G$64,"<="&$B$3)) -> 0 | J5: =IF(C5="","",H5-I5) -> 17 | L5: =IF(C5="","",IF(AND(D5<>"",D5<=$B$3),"離職結算",IF(AND(MONTH($B$3)=12,DAY($B$3)=31),"年度結算",""))) | M5: =IF(OR(C5="",L5=""),0,N(G5)-MIN(N(G5),I5)) -> 0 | N5: =IF(OR(C5="",L5=""),0,IF(L5="離職結算",J5-M5,MAX(0,J5-M5-N(K5)))) -> 0 | O5: =IF(C5="","",IFERROR(ROUND((INDEX(流程1_月結表!$G$6:$G$8,MATCH(A5,流程1_月結表!$B$6:$B$8,0))+INDEX(流程1_月結表!$H$6:$H$8,MATCH(A5,流程1_月結表!$B$6:$B$8,0))*流程1_參數!$C$7)/流程1_參數!$C$5,2),0)) -> 2100 | Q5: =IF(OR(C5="",L5=""),0,ROUND(N5*O5+M5*IF(P5="",O5,P5),0)) -> 0 | R5: =IF($C5="","",SUMIFS(流程1_請假申請!$I$5:$I$64,流程1_請假申請!$D$5:$D$64,$B5,流程1_請假申請!$F$5:$F$64,"病假（普通傷病假）",流程1_請假申請!$M$5:$M$64,"已確認",流程1_請假申請!$G$5:$G$64,">="&DATE(YEAR($B$3),1,1),流程1_請假申請!$G$5:$G$64,"<="&$B$3)) -> 2 | S5: =IF($C5="","",SUMIFS(流程1_請假申請!$I$5:$I$64,流程1_請假申請!$D$5:$D$64,$B5,流程1_請假申請!$F$5:$F$64,"事假",流程1_請假申請!$M$5:$M$64,"已確認",流程1_請假申請!$G$5:$G$64,">="&DATE(YEAR($B$3),1,1),流程1_請假申請!$G$5:$G$64,"<="&$B$3)) -> 0 | T5: =IF($C5="","",SUMIFS(流程1_請假申請!$I$5:$I$64,流程1_請假申請!$D$5:$D$64,$B5,流程1_請假申請!$F$5:$F$64,"家庭照顧假",流程1_請假申請!$M$5:$M$64,"已確認",流程1_請假申請!$G$5:$G$64,">="&DATE(YEAR($B$3),1,1),流程1_請假申請!$G$5:$G$64,"<="&$B$3)) -> 0 | U5: =IF($C5="","",SUMIFS(流程1_請假申請!$I$5:$I$64,流程1_請假申請!$D$5:$D$64,$B5,流程1_請假申請!$F$5:$F$64,"生理假",流程1_請假申請!$M$5:$M$64,"已確認",流程1_請假申請!$G$5:$G$64,">="&DATE(YEAR($B$3),1,1),流程1_請假申請!$G$5:$G$64,"<="&$B$3)) -> 0 | V5: =IF($C5="","",SUMIFS(流程1_請假申請!$I$5:$I$64,流程1_請假申請!$D$5:$D$64,$B5,流程1_請假申請!$F$5:$F$64,"安胎休養假",流程1_請假申請!$M$5:$M$64,"已確認",流程1_請假申請!$G$5:$G$64,">="&DATE(YEAR($B$3),1,1),流程1_請假申請!$G$5:$G$64,"<="&$B$3)) -> 0 | W5: =IF($C5="","",SUMIFS(流程1_請假申請!$I$5:$I$64,流程1_請假申請!$D$5:$D$64,$B5,流程1_請假申請!$F$5:$F$64,"婚假",流程1_請假申請!$M$5:$M$64,"已確認",流程1_請假申請!$G$5:$G$64,">="&DATE(YEAR($B$3),1,1),流程1_請假申請!$G$5:$G$64,"<="&$B$3)) -> 0 | X5: =IF($C5="","",SUMIFS(流程1_請假申請!$I$5:$I$64,流程1_請假申請!$D$5:$D$64,$B5,流程1_請假申請!$F$5:$F$64,"喪假",流程1_請假申請!$M$5:$M$64,"已確認",流程1_請假申請!$G$5:$G$64,">="&DATE(YEAR($B$3),1,1),流程1_請假申請!$G$5:$G$64,"<="&$B$3)) -> 0 | Y5: =IF($C5="","",SUMIFS(流程1_請假申請!$I$5:$I$64,流程1_請假申請!$D$5:$D$64,$B5,流程1_請假申請!$F$5:$F$64,"產假",流程1_請假申請!$M$5:$M$64,"已確認",流程1_請假申請!$G$5:$G$64,">="&DATE(YEAR($B$3),1,1),流程1_請假申請!$G$5:$G$64,"<="&$B$3)) -> 0 | Z5: =IF($C5="","",SUMIFS(流程1_請假申請!$I$5:$I$64,流程1_請假申請!$D$5:$D$64,$B5,流程1_請假申請!$F$5:$F$64,"產檢假",流程1_請假申請!$M$5:$M$64,"已確認",流程1_請假申請!$G$5:$G$64,">="&DATE(YEAR($B$3),1,1),流程1_請假申請!$G$5:$G$64,"<="&$B$3)) -> 0 | AA5: =IF($C5="","",SUMIFS(流程1_請假申請!$I$5:$I$64,流程1_請假申請!$D$5:$D$64,$B5,流程1_請假申請!$F$5:$F$64,"陪產檢及陪產假",流程1_請假申請!$M$5:$M$64,"已確認",流程1_請假申請!$G$5:$G$64,">="&DATE(YEAR($B$3),1,1),流程1_請假申請!$G$5:$G$64,"<="&$B$3)) -> 0 | AB5: =IF($C5="","",SUMIFS(流程1_請假申請!$I$5:$I$64,流程1_請假申請!$D$5:$D$64,$B5,流程1_請假申請!$F$5:$F$64,"公傷病假",流程1_請假申請!$M$5:$M$64,"已確認",流程1_請假申請!$G$5:$G$64,">="&DATE(YEAR($B$3),1,1),流程1_請假申請!$G$5:$G$64,"<="&$B$3)) -> 0 | AC5: =IF($C5="","",SUMIFS(流程1_請假申請!$I$5:$I$64,流程1_請假申請!$D$5:$D$64,$B5,流程1_請假申請!$F$5:$F$64,"公假",流程1_請假申請!$M$5:$M$64,"已確認",流程1_請假申請!$G$5:$G$64,">="&DATE(YEAR($B$3),1,1),流程1_請假申請!$G$5:$G$64,"<="&$B$3)) -> 0 | AD5: =IF($C5="","",SUMIFS(流程1_請假申請!$I$5:$I$64,流程1_請假申請!$D$5:$D$64,$B5,流程1_請假申請!$F$5:$F$64,"特別休假",流程1_請假申請!$M$5:$M$64,"已確認",流程1_請假申請!$G$5:$G$64,">="&DATE(YEAR($B$3),1,1),流程1_請假申請!$G$5:$G$64,"<="&$B$3)) -> 0 | AE5: =IF($C5="","",SUMIFS(流程1_請假申請!$I$5:$I$64,流程1_請假申請!$D$5:$D$64,$B5,流程1_請假申請!$F$5:$F$64,"育嬰留職停薪",流程1_請假申請!$M$5:$M$64,"已確認",流程1_請假申請!$G$5:$G$64,">="&DATE(YEAR($B$3),1,1),流程1_請假申請!$G$5:$G$64,"<="&$B$3)) -> 0 | AF5: =IF(C5="","",30-R5) -> 28 | AG5: =IF(C5="","",14-S5) -> 14 | AH5: =IF(C5="","",IF(D5="",DATE(YEAR($B$3)+1,1,1),MIN(DATE(YEAR($B$3)+1,1,1),D5+1))) -> 46388 | AI5: =IF(C5="","",MAX(DATE(YEAR($B$3),1,1),MIN(AH5,EDATE(C5,6)))) -> 46023 | AJ5: =IF(C5="","",MAX(AI5,MIN(AH5,EDATE(C5,12*MAX(1,YEAR($B$3)-YEAR(C5)))))) -> 46082 | AK5: =IF(C5="","",IF(IF(DATE(YEAR($B$3),1,1)<$C5,0,DATEDIF($C5,DATE(YEAR($B$3),1,1),"m"))<6,0,IF(IF(DATE(YEAR($B$3),1,1)<$C5,0,DATEDIF($C5,DATE(YEAR($B$3),1,1),"m"))<12,6,IF(IF(DATE(YEAR($B$3),1,1)<$C5,0,DATEDIF($C5,DATE(YEAR($B$3),1,1),"m"))<24,7,IF(IF(DATE(YEAR($B$3),1,1)<$C5,0,DATEDIF($C5,DATE(YEAR($B$3),1,1),"m"))<36,10,IF(IF(DATE(YEAR($B$3),1,1)<$C5,0,DATEDIF($C5,DATE(YEAR($B$3),1,1),"m"))<60,14,IF(IF(DATE(YEAR($B$3),1,1)<$C5,0,DATEDIF($C5,DATE(YEAR($B$3),1,1),"m"))<120,15,MIN(30,15+INT(IF(DATE(YEAR($B$3),1,1)<$C5,0,DATEDIF($C5,DATE(YEAR($B$3),1,1),"m"))/12)-9)))))))) -> 16 | AL5: =IF(C5="","",IF(IF(AI5<$C5,0,DATEDIF($C5,AI5,"m"))<6,0,IF(IF(AI5<$C5,0,DATEDIF($C5,AI5,"m"))<12,6,IF(IF(AI5<$C5,0,DATEDIF($C5,AI5,"m"))<24,7,IF(IF(AI5<$C5,0,DATEDIF($C5,AI5,"m"))<36,10,IF(IF(AI5<$C5,0,DATEDIF($C5,AI5,"m"))<60,14,IF(IF(AI5<$C5,0,DATEDIF($C5,AI5,"m"))<120,15,MIN(30,15+INT(IF(AI5<$C5,0,DATEDIF($C5,AI5,"m"))/12)-9)))))))) -> 16 | AM5: =IF(C5="","",IF(IF(AJ5<$C5,0,DATEDIF($C5,AJ5,"m"))<6,0,IF(IF(AJ5<$C5,0,DATEDIF($C5,AJ5,"m"))<12,6,IF(IF(AJ5<$C5,0,DATEDIF($C5,AJ5,"m"))<24,7,IF(IF(AJ5<$C5,0,DATEDIF($C5,AJ5,"m"))<36,10,IF(IF(AJ5<$C5,0,DATEDIF($C5,AJ5,"m"))<60,14,IF(IF(AJ5<$C5,0,DATEDIF($C5,AJ5,"m"))<120,15,MIN(30,15+INT(IF(AJ5<$C5,0,DATEDIF($C5,AJ5,"m"))/12)-9)))))))) -> 17 | AN5: =IF(C5="","",((AI5-DATE(YEAR($B$3),1,1))*AK5+(AJ5-AI5)*AL5+(AH5-AJ5)*AM5)/(DATE(YEAR($B$3)+1,1,1)-DATE(YEAR($B$3),1,1))) -> 16.838356
A6: =IF(流程1_請假申請!U6="","",流程1_請假申請!T6) -> E002 | B6: =IF(流程1_請假申請!U6="","",流程1_請假申請!U6) -> 範例員工B | C6: =IF(流程1_請假申請!U6="","",流程1_請假申請!W6) -> 43661 | D6: =IF(流程1_請假申請!X6="","",流程1_請假申請!X6) | E6: =IF(C6="","",IF($B$3<C6,0,DATEDIF(C6,$B$3,"m"))) -> 87 | F6: =IF(C6="","",IF(AN6=0,0,CEILING(ROUND(AN6,2),$E$3))) -> 15 | H6: =IF(C6="","",F6+G6) -> 15 | I6: =IF(C6="","",SUMIFS(流程1_請假申請!$I$5:$I$64,流程1_請假申請!$D$5:$D$64,B6,流程1_請假申請!$F$5:$F$64,"特別休假",流程1_請假申請!$M$5:$M$64,"已確認",流程1_請假申請!$G$5:$G$64,">="&DATE(YEAR($B$3),1,1),流程1_請假申請!$G$5:$G$64,"<="&$B$3)) -> 1 | J6: =IF(C6="","",H6-I6) -> 14 | L6: =IF(C6="","",IF(AND(D6<>"",D6<=$B$3),"離職結算",IF(AND(MONTH($B$3)=12,DAY($B$3)=31),"年度結算",""))) | M6: =IF(OR(C6="",L6=""),0,N(G6)-MIN(N(G6),I6)) -> 0 | N6: =IF(OR(C6="",L6=""),0,IF(L6="離職結算",J6-M6,MAX(0,J6-M6-N(K6)))) -> 0 | O6: =IF(C6="","",IFERROR(ROUND((INDEX(流程1_月結表!$G$6:$G$8,MATCH(A6,流程1_月結表!$B$6:$B$8,0))+INDEX(流程1_月結表!$H$6:$H$8,MATCH(A6,流程1_月結表!$B$6:$B$8,0))*流程1_參數!$C$7)/流程1_參數!$C$5,2),0)) -> 2266.67 | Q6: =IF(OR(C6="",L6=""),0,ROUND(N6*O6+M6*IF(P6="",O6,P6),0)) -> 0 | R6: =IF($C6="","",SUMIFS(流程1_請假申請!$I$5:$I$64,流程1_請假申請!$D$5:$D$64,$B6,流程1_請假申請!$F$5:$F$64,"病假（普通傷病假）",流程1_請假申請!$M$5:$M$64,"已確認",流程1_請假申請!$G$5:$G$64,">="&DATE(YEAR($B$3),1,1),流程1_請假申請!$G$5:$G$64,"<="&$B$3)) -> 0 | S6: =IF($C6="","",SUMIFS(流程1_請假申請!$I$5:$I$64,流程1_請假申請!$D$5:$D$64,$B6,流程1_請假申請!$F$5:$F$64,"事假",流程1_請假申請!$M$5:$M$64,"已確認",流程1_請假申請!$G$5:$G$64,">="&DATE(YEAR($B$3),1,1),流程1_請假申請!$G$5:$G$64,"<="&$B$3)) -> 1 | T6: =IF($C6="","",SUMIFS(流程1_請假申請!$I$5:$I$64,流程1_請假申請!$D$5:$D$64,$B6,流程1_請假申請!$F$5:$F$64,"家庭照顧假",流程1_請假申請!$M$5:$M$64,"已確認",流程1_請假申請!$G$5:$G$64,">="&DATE(YEAR($B$3),1,1),流程1_請假申請!$G$5:$G$64,"<="&$B$3)) -> 0 | U6: =IF($C6="","",SUMIFS(流程1_請假申請!$I$5:$I$64,流程1_請假申請!$D$5:$D$64,$B6,流程1_請假申請!$F$5:$F$64,"生理假",流程1_請假申請!$M$5:$M$64,"已確認",流程1_請假申請!$G$5:$G$64,">="&DATE(YEAR($B$3),1,1),流程1_請假申請!$G$5:$G$64,"<="&$B$3)) -> 0 | V6: =IF($C6="","",SUMIFS(流程1_請假申請!$I$5:$I$64,流程1_請假申請!$D$5:$D$64,$B6,流程1_請假申請!$F$5:$F$64,"安胎休養假",流程1_請假申請!$M$5:$M$64,"已確認",流程1_請假申請!$G$5:$G$64,">="&DATE(YEAR($B$3),1,1),流程1_請假申請!$G$5:$G$64,"<="&$B$3)) -> 0 | W6: =IF($C6="","",SUMIFS(流程1_請假申請!$I$5:$I$64,流程1_請假申請!$D$5:$D$64,$B6,流程1_請假申請!$F$5:$F$64,"婚假",流程1_請假申請!$M$5:$M$64,"已確認",流程1_請假申請!$G$5:$G$64,">="&DATE(YEAR($B$3),1,1),流程1_請假申請!$G$5:$G$64,"<="&$B$3)) -> 0 | X6: =IF($C6="","",SUMIFS(流程1_請假申請!$I$5:$I$64,流程1_請假申請!$D$5:$D$64,$B6,流程1_請假申請!$F$5:$F$64,"喪假",流程1_請假申請!$M$5:$M$64,"已確認",流程1_請假申請!$G$5:$G$64,">="&DATE(YEAR($B$3),1,1),流程1_請假申請!$G$5:$G$64,"<="&$B$3)) -> 0 | Y6: =IF($C6="","",SUMIFS(流程1_請假申請!$I$5:$I$64,流程1_請假申請!$D$5:$D$64,$B6,流程1_請假申請!$F$5:$F$64,"產假",流程1_請假申請!$M$5:$M$64,"已確認",流程1_請假申請!$G$5:$G$64,">="&DATE(YEAR($B$3),1,1),流程1_請假申請!$G$5:$G$64,"<="&$B$3)) -> 0 | Z6: =IF($C6="","",SUMIFS(流程1_請假申請!$I$5:$I$64,流程1_請假申請!$D$5:$D$64,$B6,流程1_請假申請!$F$5:$F$64,"產檢假",流程1_請假申請!$M$5:$M$64,"已確認",流程1_請假申請!$G$5:$G$64,">="&DATE(YEAR($B$3),1,1),流程1_請假申請!$G$5:$G$64,"<="&$B$3)) -> 0 | AA6: =IF($C6="","",SUMIFS(流程1_請假申請!$I$5:$I$64,流程1_請假申請!$D$5:$D$64,$B6,流程1_請假申請!$F$5:$F$64,"陪產檢及陪產假",流程1_請假申請!$M$5:$M$64,"已確認",流程1_請假申請!$G$5:$G$64,">="&DATE(YEAR($B$3),1,1),流程1_請假申請!$G$5:$G$64,"<="&$B$3)) -> 0 | AB6: =IF($C6="","",SUMIFS(流程1_請假申請!$I$5:$I$64,流程1_請假申請!$D$5:$D$64,$B6,流程1_請假申請!$F$5:$F$64,"公傷病假",流程1_請假申請!$M$5:$M$64,"已確認",流程1_請假申請!$G$5:$G$64,">="&DATE(YEAR($B$3),1,1),流程1_請假申請!$G$5:$G$64,"<="&$B$3)) -> 0 | AC6: =IF($C6="","",SUMIFS(流程1_請假申請!$I$5:$I$64,流程1_請假申請!$D$5:$D$64,$B6,流程1_請假申請!$F$5:$F$64,"公假",流程1_請假申請!$M$5:$M$64,"已確認",流程1_請假申請!$G$5:$G$64,">="&DATE(YEAR($B$3),1,1),流程1_請假申請!$G$5:$G$64,"<="&$B$3)) -> 0 | AD6: =IF($C6="","",SUMIFS(流程1_請假申請!$I$5:$I$64,流程1_請假申請!$D$5:$D$64,$B6,流程1_請假申請!$F$5:$F$64,"特別休假",流程1_請假申請!$M$5:$M$64,"已確認",流程1_請假申請!$G$5:$G$64,">="&DATE(YEAR($B$3),1,1),流程1_請假申請!$G$5:$G$64,"<="&$B$3)) -> 1 | AE6: =IF($C6="","",SUMIFS(流程1_請假申請!$I$5:$I$64,流程1_請假申請!$D$5:$D$64,$B6,流程1_請假申請!$F$5:$F$64,"育嬰留職停薪",流程1_請假申請!$M$5:$M$64,"已確認",流程1_請假申請!$G$5:$G$64,">="&DATE(YEAR($B$3),1,1),流程1_請假申請!$G$5:$G$64,"<="&$B$3)) -> 0 | AF6: =IF(C6="","",30-R6) -> 30 | AG6: =IF(C6="","",14-S6) -> 13 | AH6: =IF(C6="","",IF(D6="",DATE(YEAR($B$3)+1,1,1),MIN(DATE(YEAR($B$3)+1,1,1),D6+1))) -> 46388 | AI6: =IF(C6="","",MAX(DATE(YEAR($B$3),1,1),MIN(AH6,EDATE(C6,6)))) -> 46023 | AJ6: =IF(C6="","",MAX(AI6,MIN(AH6,EDATE(C6,12*MAX(1,YEAR($B$3)-YEAR(C6)))))) -> 46218 | AK6: =IF(C6="","",IF(IF(DATE(YEAR($B$3),1,1)<$C6,0,DATEDIF($C6,DATE(YEAR($B$3),1,1),"m"))<6,0,IF(IF(DATE(YEAR($B$3),1,1)<$C6,0,DATEDIF($C6,DATE(YEAR($B$3),1,1),"m"))<12,6,IF(IF(DATE(YEAR($B$3),1,1)<$C6,0,DATEDIF($C6,DATE(YEAR($B$3),1,1),"m"))<24,7,IF(IF(DATE(YEAR($B$3),1,1)<$C6,0,DATEDIF($C6,DATE(YEAR($B$3),1,1),"m"))<36,10,IF(IF(DATE(YEAR($B$3),1,1)<$C6,0,DATEDIF($C6,DATE(YEAR($B$3),1,1),"m"))<60,14,IF(IF(DATE(YEAR($B$3),1,1)<$C6,0,DATEDIF($C6,DATE(YEAR($B$3),1,1),"m"))<120,15,MIN(30,15+INT(IF(DATE(YEAR($B$3),1,1)<$C6,0,DATEDIF($C6,DATE(YEAR($B$3),1,1),"m"))/12)-9)))))))) -> 15 | AL6: =IF(C6="","",IF(IF(AI6<$C6,0,DATEDIF($C6,AI6,"m"))<6,0,IF(IF(AI6<$C6,0,DATEDIF($C6,AI6,"m"))<12,6,IF(IF(AI6<$C6,0,DATEDIF($C6,AI6,"m"))<24,7,IF(IF(AI6<$C6,0,DATEDIF($C6,AI6,"m"))<36,10,IF(IF(AI6<$C6,0,DATEDIF($C6,AI6,"m"))<60,14,IF(IF(AI6<$C6,0,DATEDIF($C6,AI6,"m"))<120,15,MIN(30,15+INT(IF(AI6<$C6,0,DATEDIF($C6,AI6,"m"))/12)-9)))))))) -> 15 | AM6: =IF(C6="","",IF(IF(AJ6<$C6,0,DATEDIF($C6,AJ6,"m"))<6,0,IF(IF(AJ6<$C6,0,DATEDIF($C6,AJ6,"m"))<12,6,IF(IF(AJ6<$C6,0,DATEDIF($C6,AJ6,"m"))<24,7,IF(IF(AJ6<$C6,0,DATEDIF($C6,AJ6,"m"))<36,10,IF(IF(AJ6<$C6,0,DATEDIF($C6,AJ6,"m"))<60,14,IF(IF(AJ6<$C6,0,DATEDIF($C6,AJ6,"m"))<120,15,MIN(30,15+INT(IF(AJ6<$C6,0,DATEDIF($C6,AJ6,"m"))/12)-9)))))))) -> 15 | AN6: =IF(C6="","",((AI6-DATE(YEAR($B$3),1,1))*AK6+(AJ6-AI6)*AL6+(AH6-AJ6)*AM6)/(DATE(YEAR($B$3)+1,1,1)-DATE(YEAR($B$3),1,1))) -> 15
A7: =IF(流程1_請假申請!U7="","",流程1_請假申請!T7) -> E003 | B7: =IF(流程1_請假申請!U7="","",流程1_請假申請!U7) -> 範例員工C | C7: =IF(流程1_請假申請!U7="","",流程1_請假申請!W7) -> 44200 | D7: =IF(流程1_請假申請!X7="","",流程1_請假申請!X7) | E7: =IF(C7="","",IF($B$3<C7,0,DATEDIF(C7,$B$3,"m"))) -> 69 | F7: =IF(C7="","",IF(AN7=0,0,CEILING(ROUND(AN7,2),$E$3))) -> 15 | H7: =IF(C7="","",F7+G7) -> 15 | I7: =IF(C7="","",SUMIFS(流程1_請假申請!$I$5:$I$64,流程1_請假申請!$D$5:$D$64,B7,流程1_請假申請!$F$5:$F$64,"特別休假",流程1_請假申請!$M$5:$M$64,"已確認",流程1_請假申請!$G$5:$G$64,">="&DATE(YEAR($B$3),1,1),流程1_請假申請!$G$5:$G$64,"<="&$B$3)) -> 0 | J7: =IF(C7="","",H7-I7) -> 15 | L7: =IF(C7="","",IF(AND(D7<>"",D7<=$B$3),"離職結算",IF(AND(MONTH($B$3)=12,DAY($B$3)=31),"年度結算",""))) | M7: =IF(OR(C7="",L7=""),0,N(G7)-MIN(N(G7),I7)) -> 0 | N7: =IF(OR(C7="",L7=""),0,IF(L7="離職結算",J7-M7,MAX(0,J7-M7-N(K7)))) -> 0 | O7: =IF(C7="","",IFERROR(ROUND((INDEX(流程1_月結表!$G$6:$G$8,MATCH(A7,流程1_月結表!$B$6:$B$8,0))+INDEX(流程1_月結表!$H$6:$H$8,MATCH(A7,流程1_月結表!$B$6:$B$8,0))*流程1_參數!$C$7)/流程1_參數!$C$5,2),0)) -> 1500 | Q7: =IF(OR(C7="",L7=""),0,ROUND(N7*O7+M7*IF(P7="",O7,P7),0)) -> 0 | R7: =IF($C7="","",SUMIFS(流程1_請假申請!$I$5:$I$64,流程1_請假申請!$D$5:$D$64,$B7,流程1_請假申請!$F$5:$F$64,"病假（普通傷病假）",流程1_請假申請!$M$5:$M$64,"已確認",流程1_請假申請!$G$5:$G$64,">="&DATE(YEAR($B$3),1,1),流程1_請假申請!$G$5:$G$64,"<="&$B$3)) -> 0 | S7: =IF($C7="","",SUMIFS(流程1_請假申請!$I$5:$I$64,流程1_請假申請!$D$5:$D$64,$B7,流程1_請假申請!$F$5:$F$64,"事假",流程1_請假申請!$M$5:$M$64,"已確認",流程1_請假申請!$G$5:$G$64,">="&DATE(YEAR($B$3),1,1),流程1_請假申請!$G$5:$G$64,"<="&$B$3)) -> 0 | T7: =IF($C7="","",SUMIFS(流程1_請假申請!$I$5:$I$64,流程1_請假申請!$D$5:$D$64,$B7,流程1_請假申請!$F$5:$F$64,"家庭照顧假",流程1_請假申請!$M$5:$M$64,"已確認",流程1_請假申請!$G$5:$G$64,">="&DATE(YEAR($B$3),1,1),流程1_請假申請!$G$5:$G$64,"<="&$B$3)) -> 0 | U7: =IF($C7="","",SUMIFS(流程1_請假申請!$I$5:$I$64,流程1_請假申請!$D$5:$D$64,$B7,流程1_請假申請!$F$5:$F$64,"生理假",流程1_請假申請!$M$5:$M$64,"已確認",流程1_請假申請!$G$5:$G$64,">="&DATE(YEAR($B$3),1,1),流程1_請假申請!$G$5:$G$64,"<="&$B$3)) -> 0 | V7: =IF($C7="","",SUMIFS(流程1_請假申請!$I$5:$I$64,流程1_請假申請!$D$5:$D$64,$B7,流程1_請假申請!$F$5:$F$64,"安胎休養假",流程1_請假申請!$M$5:$M$64,"已確認",流程1_請假申請!$G$5:$G$64,">="&DATE(YEAR($B$3),1,1),流程1_請假申請!$G$5:$G$64,"<="&$B$3)) -> 0 | W7: =IF($C7="","",SUMIFS(流程1_請假申請!$I$5:$I$64,流程1_請假申請!$D$5:$D$64,$B7,流程1_請假申請!$F$5:$F$64,"婚假",流程1_請假申請!$M$5:$M$64,"已確認",流程1_請假申請!$G$5:$G$64,">="&DATE(YEAR($B$3),1,1),流程1_請假申請!$G$5:$G$64,"<="&$B$3)) -> 0 | X7: =IF($C7="","",SUMIFS(流程1_請假申請!$I$5:$I$64,流程1_請假申請!$D$5:$D$64,$B7,流程1_請假申請!$F$5:$F$64,"喪假",流程1_請假申請!$M$5:$M$64,"已確認",流程1_請假申請!$G$5:$G$64,">="&DATE(YEAR($B$3),1,1),流程1_請假申請!$G$5:$G$64,"<="&$B$3)) -> 0 | Y7: =IF($C7="","",SUMIFS(流程1_請假申請!$I$5:$I$64,流程1_請假申請!$D$5:$D$64,$B7,流程1_請假申請!$F$5:$F$64,"產假",流程1_請假申請!$M$5:$M$64,"已確認",流程1_請假申請!$G$5:$G$64,">="&DATE(YEAR($B$3),1,1),流程1_請假申請!$G$5:$G$64,"<="&$B$3)) -> 0 | Z7: =IF($C7="","",SUMIFS(流程1_請假申請!$I$5:$I$64,流程1_請假申請!$D$5:$D$64,$B7,流程1_請假申請!$F$5:$F$64,"產檢假",流程1_請假申請!$M$5:$M$64,"已確認",流程1_請假申請!$G$5:$G$64,">="&DATE(YEAR($B$3),1,1),流程1_請假申請!$G$5:$G$64,"<="&$B$3)) -> 0 | AA7: =IF($C7="","",SUMIFS(流程1_請假申請!$I$5:$I$64,流程1_請假申請!$D$5:$D$64,$B7,流程1_請假申請!$F$5:$F$64,"陪產檢及陪產假",流程1_請假申請!$M$5:$M$64,"已確認",流程1_請假申請!$G$5:$G$64,">="&DATE(YEAR($B$3),1,1),流程1_請假申請!$G$5:$G$64,"<="&$B$3)) -> 0 | AB7: =IF($C7="","",SUMIFS(流程1_請假申請!$I$5:$I$64,流程1_請假申請!$D$5:$D$64,$B7,流程1_請假申請!$F$5:$F$64,"公傷病假",流程1_請假申請!$M$5:$M$64,"已確認",流程1_請假申請!$G$5:$G$64,">="&DATE(YEAR($B$3),1,1),流程1_請假申請!$G$5:$G$64,"<="&$B$3)) -> 0 | AC7: =IF($C7="","",SUMIFS(流程1_請假申請!$I$5:$I$64,流程1_請假申請!$D$5:$D$64,$B7,流程1_請假申請!$F$5:$F$64,"公假",流程1_請假申請!$M$5:$M$64,"已確認",流程1_請假申請!$G$5:$G$64,">="&DATE(YEAR($B$3),1,1),流程1_請假申請!$G$5:$G$64,"<="&$B$3)) -> 0 | AD7: =IF($C7="","",SUMIFS(流程1_請假申請!$I$5:$I$64,流程1_請假申請!$D$5:$D$64,$B7,流程1_請假申請!$F$5:$F$64,"特別休假",流程1_請假申請!$M$5:$M$64,"已確認",流程1_請假申請!$G$5:$G$64,">="&DATE(YEAR($B$3),1,1),流程1_請假申請!$G$5:$G$64,"<="&$B$3)) -> 0 | AE7: =IF($C7="","",SUMIFS(流程1_請假申請!$I$5:$I$64,流程1_請假申請!$D$5:$D$64,$B7,流程1_請假申請!$F$5:$F$64,"育嬰留職停薪",流程1_請假申請!$M$5:$M$64,"已確認",流程1_請假申請!$G$5:$G$64,">="&DATE(YEAR($B$3),1,1),流程1_請假申請!$G$5:$G$64,"<="&$B$3)) -> 0 | AF7: =IF(C7="","",30-R7) -> 30 | AG7: =IF(C7="","",14-S7) -> 14 | AH7: =IF(C7="","",IF(D7="",DATE(YEAR($B$3)+1,1,1),MIN(DATE(YEAR($B$3)+1,1,1),D7+1))) -> 46388 | AI7: =IF(C7="","",MAX(DATE(YEAR($B$3),1,1),MIN(AH7,EDATE(C7,6)))) -> 46023 | AJ7: =IF(C7="","",MAX(AI7,MIN(AH7,EDATE(C7,12*MAX(1,YEAR($B$3)-YEAR(C7)))))) -> 46026 | AK7: =IF(C7="","",IF(IF(DATE(YEAR($B$3),1,1)<$C7,0,DATEDIF($C7,DATE(YEAR($B$3),1,1),"m"))<6,0,IF(IF(DATE(YEAR($B$3),1,1)<$C7,0,DATEDIF($C7,DATE(YEAR($B$3),1,1),"m"))<12,6,IF(IF(DATE(YEAR($B$3),1,1)<$C7,0,DATEDIF($C7,DATE(YEAR($B$3),1,1),"m"))<24,7,IF(IF(DATE(YEAR($B$3),1,1)<$C7,0,DATEDIF($C7,DATE(YEAR($B$3),1,1),"m"))<36,10,IF(IF(DATE(YEAR($B$3),1,1)<$C7,0,DATEDIF($C7,DATE(YEAR($B$3),1,1),"m"))<60,14,IF(IF(DATE(YEAR($B$3),1,1)<$C7,0,DATEDIF($C7,DATE(YEAR($B$3),1,1),"m"))<120,15,MIN(30,15+INT(IF(DATE(YEAR($B$3),1,1)<$C7,0,DATEDIF($C7,DATE(YEAR($B$3),1,1),"m"))/12)-9)))))))) -> 14 | AL7: =IF(C7="","",IF(IF(AI7<$C7,0,DATEDIF($C7,AI7,"m"))<6,0,IF(IF(AI7<$C7,0,DATEDIF($C7,AI7,"m"))<12,6,IF(IF(AI7<$C7,0,DATEDIF($C7,AI7,"m"))<24,7,IF(IF(AI7<$C7,0,DATEDIF($C7,AI7,"m"))<36,10,IF(IF(AI7<$C7,0,DATEDIF($C7,AI7,"m"))<60,14,IF(IF(AI7<$C7,0,DATEDIF($C7,AI7,"m"))<120,15,MIN(30,15+INT(IF(AI7<$C7,0,DATEDIF($C7,AI7,"m"))/12)-9)))))))) -> 14 | AM7: =IF(C7="","",IF(IF(AJ7<$C7,0,DATEDIF($C7,AJ7,"m"))<6,0,IF(IF(AJ7<$C7,0,DATEDIF($C7,AJ7,"m"))<12,6,IF(IF(AJ7<$C7,0,DATEDIF($C7,AJ7,"m"))<24,7,IF(IF(AJ7<$C7,0,DATEDIF($C7,AJ7,"m"))<36,10,IF(IF(AJ7<$C7,0,DATEDIF($C7,AJ7,"m"))<60,14,IF(IF(AJ7<$C7,0,DATEDIF($C7,AJ7,"m"))<120,15,MIN(30,15+INT(IF(AJ7<$C7,0,DATEDIF($C7,AJ7,"m"))/12)-9)))))))) -> 15 | AN7: =IF(C7="","",((AI7-DATE(YEAR($B$3),1,1))*AK7+(AJ7-AI7)*AL7+(AH7-AJ7)*AM7)/(DATE(YEAR($B$3)+1,1,1)-DATE(YEAR($B$3),1,1))) -> 14.991781
A8: =IF(流程1_請假申請!U8="","",流程1_請假申請!T8) | B8: =IF(流程1_請假申請!U8="","",流程1_請假申請!U8) | C8: =IF(流程1_請假申請!U8="","",流程1_請假申請!W8) | D8: =IF(流程1_請假申請!X8="","",流程1_請假申請!X8) | E8: =IF(C8="","",IF($B$3<C8,0,DATEDIF(C8,$B$3,"m"))) | F8: =IF(C8="","",IF(AN8=0,0,CEILING(ROUND(AN8,2),$E$3))) | H8: =IF(C8="","",F8+G8) | I8: =IF(C8="","",SUMIFS(流程1_請假申請!$I$5:$I$64,流程1_請假申請!$D$5:$D$64,B8,流程1_請假申請!$F$5:$F$64,"特別休假",流程1_請假申請!$M$5:$M$64,"已確認",流程1_請假申請!$G$5:$G$64,">="&DATE(YEAR($B$3),1,1),流程1_請假申請!$G$5:$G$64,"<="&$B$3)) | J8: =IF(C8="","",H8-I8) | L8: =IF(C8="","",IF(AND(D8<>"",D8<=$B$3),"離職結算",IF(AND(MONTH($B$3)=12,DAY($B$3)=31),"年度結算",""))) | M8: =IF(OR(C8="",L8=""),0,N(G8)-MIN(N(G8),I8)) -> 0 | N8: =IF(OR(C8="",L8=""),0,IF(L8="離職結算",J8-M8,MAX(0,J8-M8-N(K8)))) -> 0 | O8: =IF(C8="","",IFERROR(ROUND((INDEX(流程1_月結表!$G$6:$G$8,MATCH(A8,流程1_月結表!$B$6:$B$8,0))+INDEX(流程1_月結表!$H$6:$H$8,MATCH(A8,流程1_月結表!$B$6:$B$8,0))*流程1_參數!$C$7)/流程1_參數!$C$5,2),0)) | Q8: =IF(OR(C8="",L8=""),0,ROUND(N8*O8+M8*IF(P8="",O8,P8),0)) -> 0 | R8: =IF($C8="","",SUMIFS(流程1_請假申請!$I$5:$I$64,流程1_請假申請!$D$5:$D$64,$B8,流程1_請假申請!$F$5:$F$64,"病假（普通傷病假）",流程1_請假申請!$M$5:$M$64,"已確認",流程1_請假申請!$G$5:$G$64,">="&DATE(YEAR($B$3),1,1),流程1_請假申請!$G$5:$G$64,"<="&$B$3)) | S8: =IF($C8="","",SUMIFS(流程1_請假申請!$I$5:$I$64,流程1_請假申請!$D$5:$D$64,$B8,流程1_請假申請!$F$5:$F$64,"事假",流程1_請假申請!$M$5:$M$64,"已確認",流程1_請假申請!$G$5:$G$64,">="&DATE(YEAR($B$3),1,1),流程1_請假申請!$G$5:$G$64,"<="&$B$3)) | T8: =IF($C8="","",SUMIFS(流程1_請假申請!$I$5:$I$64,流程1_請假申請!$D$5:$D$64,$B8,流程1_請假申請!$F$5:$F$64,"家庭照顧假",流程1_請假申請!$M$5:$M$64,"已確認",流程1_請假申請!$G$5:$G$64,">="&DATE(YEAR($B$3),1,1),流程1_請假申請!$G$5:$G$64,"<="&$B$3)) | U8: =IF($C8="","",SUMIFS(流程1_請假申請!$I$5:$I$64,流程1_請假申請!$D$5:$D$64,$B8,流程1_請假申請!$F$5:$F$64,"生理假",流程1_請假申請!$M$5:$M$64,"已確認",流程1_請假申請!$G$5:$G$64,">="&DATE(YEAR($B$3),1,1),流程1_請假申請!$G$5:$G$64,"<="&$B$3)) | V8: =IF($C8="","",SUMIFS(流程1_請假申請!$I$5:$I$64,流程1_請假申請!$D$5:$D$64,$B8,流程1_請假申請!$F$5:$F$64,"安胎休養假",流程1_請假申請!$M$5:$M$64,"已確認",流程1_請假申請!$G$5:$G$64,">="&DATE(YEAR($B$3),1,1),流程1_請假申請!$G$5:$G$64,"<="&$B$3)) | W8: =IF($C8="","",SUMIFS(流程1_請假申請!$I$5:$I$64,流程1_請假申請!$D$5:$D$64,$B8,流程1_請假申請!$F$5:$F$64,"婚假",流程1_請假申請!$M$5:$M$64,"已確認",流程1_請假申請!$G$5:$G$64,">="&DATE(YEAR($B$3),1,1),流程1_請假申請!$G$5:$G$64,"<="&$B$3)) | X8: =IF($C8="","",SUMIFS(流程1_請假申請!$I$5:$I$64,流程1_請假申請!$D$5:$D$64,$B8,流程1_請假申請!$F$5:$F$64,"喪假",流程1_請假申請!$M$5:$M$64,"已確認",流程1_請假申請!$G$5:$G$64,">="&DATE(YEAR($B$3),1,1),流程1_請假申請!$G$5:$G$64,"<="&$B$3)) | Y8: =IF($C8="","",SUMIFS(流程1_請假申請!$I$5:$I$64,流程1_請假申請!$D$5:$D$64,$B8,流程1_請假申請!$F$5:$F$64,"產假",流程1_請假申請!$M$5:$M$64,"已確認",流程1_請假申請!$G$5:$G$64,">="&DATE(YEAR($B$3),1,1),流程1_請假申請!$G$5:$G$64,"<="&$B$3)) | Z8: =IF($C8="","",SUMIFS(流程1_請假申請!$I$5:$I$64,流程1_請假申請!$D$5:$D$64,$B8,流程1_請假申請!$F$5:$F$64,"產檢假",流程1_請假申請!$M$5:$M$64,"已確認",流程1_請假申請!$G$5:$G$64,">="&DATE(YEAR($B$3),1,1),流程1_請假申請!$G$5:$G$64,"<="&$B$3)) | AA8: =IF($C8="","",SUMIFS(流程1_請假申請!$I$5:$I$64,流程1_請假申請!$D$5:$D$64,$B8,流程1_請假申請!$F$5:$F$64,"陪產檢及陪產假",流程1_請假申請!$M$5:$M$64,"已確認",流程1_請假申請!$G$5:$G$64,">="&DATE(YEAR($B$3),1,1),流程1_請假申請!$G$5:$G$64,"<="&$B$3)) | AB8: =IF($C8="","",SUMIFS(流程1_請假申請!$I$5:$I$64,流程1_請假申請!$D$5:$D$64,$B8,流程1_請假申請!$F$5:$F$64,"公傷病假",流程1_請假申請!$M$5:$M$64,"已確認",流程1_請假申請!$G$5:$G$64,">="&DATE(YEAR($B$3),1,1),流程1_請假申請!$G$5:$G$64,"<="&$B$3)) | AC8: =IF($C8="","",SUMIFS(流程1_請假申請!$I$5:$I$64,流程1_請假申請!$D$5:$D$64,$B8,流程1_請假申請!$F$5:$F$64,"公假",流程1_請假申請!$M$5:$M$64,"已確認",流程1_請假申請!$G$5:$G$64,">="&DATE(YEAR($B$3),1,1),流程1_請假申請!$G$5:$G$64,"<="&$B$3)) | AD8: =IF($C8="","",SUMIFS(流程1_請假申請!$I$5:$I$64,流程1_請假申請!$D$5:$D$64,$B8,流程1_請假申請!$F$5:$F$64,"特別休假",流程1_請假申請!$M$5:$M$64,"已確認",流程1_請假申請!$G$5:$G$64,">="&DATE(YEAR($B$3),1,1),流程1_請假申請!$G$5:$G$64,"<="&$B$3)) | AE8: =IF($C8="","",SUMIFS(流程1_請假申請!$I$5:$I$64,流程1_請假申請!$D$5:$D$64,$B8,流程1_請假申請!$F$5:$F$64,"育嬰留職停薪",流程1_請假申請!$M$5:$M$64,"已確認",流程1_請假申請!$G$5:$G$64,">="&DATE(YEAR($B$3),1,1),流程1_請假申請!$G$5:$G$64,"<="&$B$3)) | AF8: =IF(C8="","",30-R8) | AG8: =IF(C8="","",14-S8) | AH8: =IF(C8="","",IF(D8="",DATE(YEAR($B$3)+1,1,1),MIN(DATE(YEAR($B$3)+1,1,1),D8+1))) | AI8: =IF(C8="","",MAX(DATE(YEAR($B$3),1,1),MIN(AH8,EDATE(C8,6)))) | AJ8: =IF(C8="","",MAX(AI8,MIN(AH8,EDATE(C8,12*MAX(1,YEAR($B$3)-YEAR(C8)))))) | AK8: =IF(C8="","",IF(IF(DATE(YEAR($B$3),1,1)<$C8,0,DATEDIF($C8,DATE(YEAR($B$3),1,1),"m"))<6,0,IF(IF(DATE(YEAR($B$3),1,1)<$C8,0,DATEDIF($C8,DATE(YEAR($B$3),1,1),"m"))<12,6,IF(IF(DATE(YEAR($B$3),1,1)<$C8,0,DATEDIF($C8,DATE(YEAR($B$3),1,1),"m"))<24,7,IF(IF(DATE(YEAR($B$3),1,1)<$C8,0,DATEDIF($C8,DATE(YEAR($B$3),1,1),"m"))<36,10,IF(IF(DATE(YEAR($B$3),1,1)<$C8,0,DATEDIF($C8,DATE(YEAR($B$3),1,1),"m"))<60,14,IF(IF(DATE(YEAR($B$3),1,1)<$C8,0,DATEDIF($C8,DATE(YEAR($B$3),1,1),"m"))<120,15,MIN(30,15+INT(IF(DATE(YEAR($B$3),1,1)<$C8,0,DATEDIF($C8,DATE(YEAR($B$3),1,1),"m"))/12)-9)))))))) | AL8: =IF(C8="","",IF(IF(AI8<$C8,0,DATEDIF($C8,AI8,"m"))<6,0,IF(IF(AI8<$C8,0,DATEDIF($C8,AI8,"m"))<12,6,IF(IF(AI8<$C8,0,DATEDIF($C8,AI8,"m"))<24,7,IF(IF(AI8<$C8,0,DATEDIF($C8,AI8,"m"))<36,10,IF(IF(AI8<$C8,0,DATEDIF($C8,AI8,"m"))<60,14,IF(IF(AI8<$C8,0,DATEDIF($C8,AI8,"m"))<120,15,MIN(30,15+INT(IF(AI8<$C8,0,DATEDIF($C8,AI8,"m"))/12)-9)))))))) | AM8: =IF(C8="","",IF(IF(AJ8<$C8,0,DATEDIF($C8,AJ8,"m"))<6,0,IF(IF(AJ8<$C8,0,DATEDIF($C8,AJ8,"m"))<12,6,IF(IF(AJ8<$C8,0,DATEDIF($C8,AJ8,"m"))<24,7,IF(IF(AJ8<$C8,0,DATEDIF($C8,AJ8,"m"))<36,10,IF(IF(AJ8<$C8,0,DATEDIF($C8,AJ8,"m"))<60,14,IF(IF(AJ8<$C8,0,DATEDIF($C8,AJ8,"m"))<120,15,MIN(30,15+INT(IF(AJ8<$C8,0,DATEDIF($C8,AJ8,"m"))/12)-9)))))))) | AN8: =IF(C8="","",((AI8-DATE(YEAR($B$3),1,1))*AK8+(AJ8-AI8)*AL8+(AH8-AJ8)*AM8)/(DATE(YEAR($B$3)+1,1,1)-DATE(YEAR($B$3),1,1)))
A9: =IF(流程1_請假申請!U9="","",流程1_請假申請!T9) | B9: =IF(流程1_請假申請!U9="","",流程1_請假申請!U9) | C9: =IF(流程1_請假申請!U9="","",流程1_請假申請!W9) | D9: =IF(流程1_請假申請!X9="","",流程1_請假申請!X9) | E9: =IF(C9="","",IF($B$3<C9,0,DATEDIF(C9,$B$3,"m"))) | F9: =IF(C9="","",IF(AN9=0,0,CEILING(ROUND(AN9,2),$E$3))) | H9: =IF(C9="","",F9+G9) | I9: =IF(C9="","",SUMIFS(流程1_請假申請!$I$5:$I$64,流程1_請假申請!$D$5:$D$64,B9,流程1_請假申請!$F$5:$F$64,"特別休假",流程1_請假申請!$M$5:$M$64,"已確認",流程1_請假申請!$G$5:$G$64,">="&DATE(YEAR($B$3),1,1),流程1_請假申請!$G$5:$G$64,"<="&$B$3)) | J9: =IF(C9="","",H9-I9) | L9: =IF(C9="","",IF(AND(D9<>"",D9<=$B$3),"離職結算",IF(AND(MONTH($B$3)=12,DAY($B$3)=31),"年度結算",""))) | M9: =IF(OR(C9="",L9=""),0,N(G9)-MIN(N(G9),I9)) -> 0 | N9: =IF(OR(C9="",L9=""),0,IF(L9="離職結算",J9-M9,MAX(0,J9-M9-N(K9)))) -> 0 | O9: =IF(C9="","",IFERROR(ROUND((INDEX(流程1_月結表!$G$6:$G$8,MATCH(A9,流程1_月結表!$B$6:$B$8,0))+INDEX(流程1_月結表!$H$6:$H$8,MATCH(A9,流程1_月結表!$B$6:$B$8,0))*流程1_參數!$C$7)/流程1_參數!$C$5,2),0)) | Q9: =IF(OR(C9="",L9=""),0,ROUND(N9*O9+M9*IF(P9="",O9,P9),0)) -> 0 | R9: =IF($C9="","",SUMIFS(流程1_請假申請!$I$5:$I$64,流程1_請假申請!$D$5:$D$64,$B9,流程1_請假申請!$F$5:$F$64,"病假（普通傷病假）",流程1_請假申請!$M$5:$M$64,"已確認",流程1_請假申請!$G$5:$G$64,">="&DATE(YEAR($B$3),1,1),流程1_請假申請!$G$5:$G$64,"<="&$B$3)) | S9: =IF($C9="","",SUMIFS(流程1_請假申請!$I$5:$I$64,流程1_請假申請!$D$5:$D$64,$B9,流程1_請假申請!$F$5:$F$64,"事假",流程1_請假申請!$M$5:$M$64,"已確認",流程1_請假申請!$G$5:$G$64,">="&DATE(YEAR($B$3),1,1),流程1_請假申請!$G$5:$G$64,"<="&$B$3)) | T9: =IF($C9="","",SUMIFS(流程1_請假申請!$I$5:$I$64,流程1_請假申請!$D$5:$D$64,$B9,流程1_請假申請!$F$5:$F$64,"家庭照顧假",流程1_請假申請!$M$5:$M$64,"已確認",流程1_請假申請!$G$5:$G$64,">="&DATE(YEAR($B$3),1,1),流程1_請假申請!$G$5:$G$64,"<="&$B$3)) | U9: =IF($C9="","",SUMIFS(流程1_請假申請!$I$5:$I$64,流程1_請假申請!$D$5:$D$64,$B9,流程1_請假申請!$F$5:$F$64,"生理假",流程1_請假申請!$M$5:$M$64,"已確認",流程1_請假申請!$G$5:$G$64,">="&DATE(YEAR($B$3),1,1),流程1_請假申請!$G$5:$G$64,"<="&$B$3)) | V9: =IF($C9="","",SUMIFS(流程1_請假申請!$I$5:$I$64,流程1_請假申請!$D$5:$D$64,$B9,流程1_請假申請!$F$5:$F$64,"安胎休養假",流程1_請假申請!$M$5:$M$64,"已確認",流程1_請假申請!$G$5:$G$64,">="&DATE(YEAR($B$3),1,1),流程1_請假申請!$G$5:$G$64,"<="&$B$3)) | W9: =IF($C9="","",SUMIFS(流程1_請假申請!$I$5:$I$64,流程1_請假申請!$D$5:$D$64,$B9,流程1_請假申請!$F$5:$F$64,"婚假",流程1_請假申請!$M$5:$M$64,"已確認",流程1_請假申請!$G$5:$G$64,">="&DATE(YEAR($B$3),1,1),流程1_請假申請!$G$5:$G$64,"<="&$B$3)) | X9: =IF($C9="","",SUMIFS(流程1_請假申請!$I$5:$I$64,流程1_請假申請!$D$5:$D$64,$B9,流程1_請假申請!$F$5:$F$64,"喪假",流程1_請假申請!$M$5:$M$64,"已確認",流程1_請假申請!$G$5:$G$64,">="&DATE(YEAR($B$3),1,1),流程1_請假申請!$G$5:$G$64,"<="&$B$3)) | Y9: =IF($C9="","",SUMIFS(流程1_請假申請!$I$5:$I$64,流程1_請假申請!$D$5:$D$64,$B9,流程1_請假申請!$F$5:$F$64,"產假",流程1_請假申請!$M$5:$M$64,"已確認",流程1_請假申請!$G$5:$G$64,">="&DATE(YEAR($B$3),1,1),流程1_請假申請!$G$5:$G$64,"<="&$B$3)) | Z9: =IF($C9="","",SUMIFS(流程1_請假申請!$I$5:$I$64,流程1_請假申請!$D$5:$D$64,$B9,流程1_請假申請!$F$5:$F$64,"產檢假",流程1_請假申請!$M$5:$M$64,"已確認",流程1_請假申請!$G$5:$G$64,">="&DATE(YEAR($B$3),1,1),流程1_請假申請!$G$5:$G$64,"<="&$B$3)) | AA9: =IF($C9="","",SUMIFS(流程1_請假申請!$I$5:$I$64,流程1_請假申請!$D$5:$D$64,$B9,流程1_請假申請!$F$5:$F$64,"陪產檢及陪產假",流程1_請假申請!$M$5:$M$64,"已確認",流程1_請假申請!$G$5:$G$64,">="&DATE(YEAR($B$3),1,1),流程1_請假申請!$G$5:$G$64,"<="&$B$3)) | AB9: =IF($C9="","",SUMIFS(流程1_請假申請!$I$5:$I$64,流程1_請假申請!$D$5:$D$64,$B9,流程1_請假申請!$F$5:$F$64,"公傷病假",流程1_請假申請!$M$5:$M$64,"已確認",流程1_請假申請!$G$5:$G$64,">="&DATE(YEAR($B$3),1,1),流程1_請假申請!$G$5:$G$64,"<="&$B$3)) | AC9: =IF($C9="","",SUMIFS(流程1_請假申請!$I$5:$I$64,流程1_請假申請!$D$5:$D$64,$B9,流程1_請假申請!$F$5:$F$64,"公假",流程1_請假申請!$M$5:$M$64,"已確認",流程1_請假申請!$G$5:$G$64,">="&DATE(YEAR($B$3),1,1),流程1_請假申請!$G$5:$G$64,"<="&$B$3)) | AD9: =IF($C9="","",SUMIFS(流程1_請假申請!$I$5:$I$64,流程1_請假申請!$D$5:$D$64,$B9,流程1_請假申請!$F$5:$F$64,"特別休假",流程1_請假申請!$M$5:$M$64,"已確認",流程1_請假申請!$G$5:$G$64,">="&DATE(YEAR($B$3),1,1),流程1_請假申請!$G$5:$G$64,"<="&$B$3)) | AE9: =IF($C9="","",SUMIFS(流程1_請假申請!$I$5:$I$64,流程1_請假申請!$D$5:$D$64,$B9,流程1_請假申請!$F$5:$F$64,"育嬰留職停薪",流程1_請假申請!$M$5:$M$64,"已確認",流程1_請假申請!$G$5:$G$64,">="&DATE(YEAR($B$3),1,1),流程1_請假申請!$G$5:$G$64,"<="&$B$3)) | AF9: =IF(C9="","",30-R9) | AG9: =IF(C9="","",14-S9) | AH9: =IF(C9="","",IF(D9="",DATE(YEAR($B$3)+1,1,1),MIN(DATE(YEAR($B$3)+1,1,1),D9+1))) | AI9: =IF(C9="","",MAX(DATE(YEAR($B$3),1,1),MIN(AH9,EDATE(C9,6)))) | AJ9: =IF(C9="","",MAX(AI9,MIN(AH9,EDATE(C9,12*MAX(1,YEAR($B$3)-YEAR(C9)))))) | AK9: =IF(C9="","",IF(IF(DATE(YEAR($B$3),1,1)<$C9,0,DATEDIF($C9,DATE(YEAR($B$3),1,1),"m"))<6,0,IF(IF(DATE(YEAR($B$3),1,1)<$C9,0,DATEDIF($C9,DATE(YEAR($B$3),1,1),"m"))<12,6,IF(IF(DATE(YEAR($B$3),1,1)<$C9,0,DATEDIF($C9,DATE(YEAR($B$3),1,1),"m"))<24,7,IF(IF(DATE(YEAR($B$3),1,1)<$C9,0,DATEDIF($C9,DATE(YEAR($B$3),1,1),"m"))<36,10,IF(IF(DATE(YEAR($B$3),1,1)<$C9,0,DATEDIF($C9,DATE(YEAR($B$3),1,1),"m"))<60,14,IF(IF(DATE(YEAR($B$3),1,1)<$C9,0,DATEDIF($C9,DATE(YEAR($B$3),1,1),"m"))<120,15,MIN(30,15+INT(IF(DATE(YEAR($B$3),1,1)<$C9,0,DATEDIF($C9,DATE(YEAR($B$3),1,1),"m"))/12)-9)))))))) | AL9: =IF(C9="","",IF(IF(AI9<$C9,0,DATEDIF($C9,AI9,"m"))<6,0,IF(IF(AI9<$C9,0,DATEDIF($C9,AI9,"m"))<12,6,IF(IF(AI9<$C9,0,DATEDIF($C9,AI9,"m"))<24,7,IF(IF(AI9<$C9,0,DATEDIF($C9,AI9,"m"))<36,10,IF(IF(AI9<$C9,0,DATEDIF($C9,AI9,"m"))<60,14,IF(IF(AI9<$C9,0,DATEDIF($C9,AI9,"m"))<120,15,MIN(30,15+INT(IF(AI9<$C9,0,DATEDIF($C9,AI9,"m"))/12)-9)))))))) | AM9: =IF(C9="","",IF(IF(AJ9<$C9,0,DATEDIF($C9,AJ9,"m"))<6,0,IF(IF(AJ9<$C9,0,DATEDIF($C9,AJ9,"m"))<12,6,IF(IF(AJ9<$C9,0,DATEDIF($C9,AJ9,"m"))<24,7,IF(IF(AJ9<$C9,0,DATEDIF($C9,AJ9,"m"))<36,10,IF(IF(AJ9<$C9,0,DATEDIF($C9,AJ9,"m"))<60,14,IF(IF(AJ9<$C9,0,DATEDIF($C9,AJ9,"m"))<120,15,MIN(30,15+INT(IF(AJ9<$C9,0,DATEDIF($C9,AJ9,"m"))/12)-9)))))))) | AN9: =IF(C9="","",((AI9-DATE(YEAR($B$3),1,1))*AK9+(AJ9-AI9)*AL9+(AH9-AJ9)*AM9)/(DATE(YEAR($B$3)+1,1,1)-DATE(YEAR($B$3),1,1)))
A10: =IF(流程1_請假申請!U10="","",流程1_請假申請!T10) | B10: =IF(流程1_請假申請!U10="","",流程1_請假申請!U10) | C10: =IF(流程1_請假申請!U10="","",流程1_請假申請!W10) | D10: =IF(流程1_請假申請!X10="","",流程1_請假申請!X10) | E10: =IF(C10="","",IF($B$3<C10,0,DATEDIF(C10,$B$3,"m"))) | F10: =IF(C10="","",IF(AN10=0,0,CEILING(ROUND(AN10,2),$E$3))) | H10: =IF(C10="","",F10+G10) | I10: =IF(C10="","",SUMIFS(流程1_請假申請!$I$5:$I$64,流程1_請假申請!$D$5:$D$64,B10,流程1_請假申請!$F$5:$F$64,"特別休假",流程1_請假申請!$M$5:$M$64,"已確認",流程1_請假申請!$G$5:$G$64,">="&DATE(YEAR($B$3),1,1),流程1_請假申請!$G$5:$G$64,"<="&$B$3)) | J10: =IF(C10="","",H10-I10) | L10: =IF(C10="","",IF(AND(D10<>"",D10<=$B$3),"離職結算",IF(AND(MONTH($B$3)=12,DAY($B$3)=31),"年度結算",""))) | M10: =IF(OR(C10="",L10=""),0,N(G10)-MIN(N(G10),I10)) -> 0 | N10: =IF(OR(C10="",L10=""),0,IF(L10="離職結算",J10-M10,MAX(0,J10-M10-N(K10)))) -> 0 | O10: =IF(C10="","",IFERROR(ROUND((INDEX(流程1_月結表!$G$6:$G$8,MATCH(A10,流程1_月結表!$B$6:$B$8,0))+INDEX(流程1_月結表!$H$6:$H$8,MATCH(A10,流程1_月結表!$B$6:$B$8,0))*流程1_參數!$C$7)/流程1_參數!$C$5,2),0)) | Q10: =IF(OR(C10="",L10=""),0,ROUND(N10*O10+M10*IF(P10="",O10,P10),0)) -> 0 | R10: =IF($C10="","",SUMIFS(流程1_請假申請!$I$5:$I$64,流程1_請假申請!$D$5:$D$64,$B10,流程1_請假申請!$F$5:$F$64,"病假（普通傷病假）",流程1_請假申請!$M$5:$M$64,"已確認",流程1_請假申請!$G$5:$G$64,">="&DATE(YEAR($B$3),1,1),流程1_請假申請!$G$5:$G$64,"<="&$B$3)) | S10: =IF($C10="","",SUMIFS(流程1_請假申請!$I$5:$I$64,流程1_請假申請!$D$5:$D$64,$B10,流程1_請假申請!$F$5:$F$64,"事假",流程1_請假申請!$M$5:$M$64,"已確認",流程1_請假申請!$G$5:$G$64,">="&DATE(YEAR($B$3),1,1),流程1_請假申請!$G$5:$G$64,"<="&$B$3)) | T10: =IF($C10="","",SUMIFS(流程1_請假申請!$I$5:$I$64,流程1_請假申請!$D$5:$D$64,$B10,流程1_請假申請!$F$5:$F$64,"家庭照顧假",流程1_請假申請!$M$5:$M$64,"已確認",流程1_請假申請!$G$5:$G$64,">="&DATE(YEAR($B$3),1,1),流程1_請假申請!$G$5:$G$64,"<="&$B$3)) | U10: =IF($C10="","",SUMIFS(流程1_請假申請!$I$5:$I$64,流程1_請假申請!$D$5:$D$64,$B10,流程1_請假申請!$F$5:$F$64,"生理假",流程1_請假申請!$M$5:$M$64,"已確認",流程1_請假申請!$G$5:$G$64,">="&DATE(YEAR($B$3),1,1),流程1_請假申請!$G$5:$G$64,"<="&$B$3)) | V10: =IF($C10="","",SUMIFS(流程1_請假申請!$I$5:$I$64,流程1_請假申請!$D$5:$D$64,$B10,流程1_請假申請!$F$5:$F$64,"安胎休養假",流程1_請假申請!$M$5:$M$64,"已確認",流程1_請假申請!$G$5:$G$64,">="&DATE(YEAR($B$3),1,1),流程1_請假申請!$G$5:$G$64,"<="&$B$3)) | W10: =IF($C10="","",SUMIFS(流程1_請假申請!$I$5:$I$64,流程1_請假申請!$D$5:$D$64,$B10,流程1_請假申請!$F$5:$F$64,"婚假",流程1_請假申請!$M$5:$M$64,"已確認",流程1_請假申請!$G$5:$G$64,">="&DATE(YEAR($B$3),1,1),流程1_請假申請!$G$5:$G$64,"<="&$B$3)) | X10: =IF($C10="","",SUMIFS(流程1_請假申請!$I$5:$I$64,流程1_請假申請!$D$5:$D$64,$B10,流程1_請假申請!$F$5:$F$64,"喪假",流程1_請假申請!$M$5:$M$64,"已確認",流程1_請假申請!$G$5:$G$64,">="&DATE(YEAR($B$3),1,1),流程1_請假申請!$G$5:$G$64,"<="&$B$3)) | Y10: =IF($C10="","",SUMIFS(流程1_請假申請!$I$5:$I$64,流程1_請假申請!$D$5:$D$64,$B10,流程1_請假申請!$F$5:$F$64,"產假",流程1_請假申請!$M$5:$M$64,"已確認",流程1_請假申請!$G$5:$G$64,">="&DATE(YEAR($B$3),1,1),流程1_請假申請!$G$5:$G$64,"<="&$B$3)) | Z10: =IF($C10="","",SUMIFS(流程1_請假申請!$I$5:$I$64,流程1_請假申請!$D$5:$D$64,$B10,流程1_請假申請!$F$5:$F$64,"產檢假",流程1_請假申請!$M$5:$M$64,"已確認",流程1_請假申請!$G$5:$G$64,">="&DATE(YEAR($B$3),1,1),流程1_請假申請!$G$5:$G$64,"<="&$B$3)) | AA10: =IF($C10="","",SUMIFS(流程1_請假申請!$I$5:$I$64,流程1_請假申請!$D$5:$D$64,$B10,流程1_請假申請!$F$5:$F$64,"陪產檢及陪產假",流程1_請假申請!$M$5:$M$64,"已確認",流程1_請假申請!$G$5:$G$64,">="&DATE(YEAR($B$3),1,1),流程1_請假申請!$G$5:$G$64,"<="&$B$3)) | AB10: =IF($C10="","",SUMIFS(流程1_請假申請!$I$5:$I$64,流程1_請假申請!$D$5:$D$64,$B10,流程1_請假申請!$F$5:$F$64,"公傷病假",流程1_請假申請!$M$5:$M$64,"已確認",流程1_請假申請!$G$5:$G$64,">="&DATE(YEAR($B$3),1,1),流程1_請假申請!$G$5:$G$64,"<="&$B$3)) | AC10: =IF($C10="","",SUMIFS(流程1_請假申請!$I$5:$I$64,流程1_請假申請!$D$5:$D$64,$B10,流程1_請假申請!$F$5:$F$64,"公假",流程1_請假申請!$M$5:$M$64,"已確認",流程1_請假申請!$G$5:$G$64,">="&DATE(YEAR($B$3),1,1),流程1_請假申請!$G$5:$G$64,"<="&$B$3)) | AD10: =IF($C10="","",SUMIFS(流程1_請假申請!$I$5:$I$64,流程1_請假申請!$D$5:$D$64,$B10,流程1_請假申請!$F$5:$F$64,"特別休假",流程1_請假申請!$M$5:$M$64,"已確認",流程1_請假申請!$G$5:$G$64,">="&DATE(YEAR($B$3),1,1),流程1_請假申請!$G$5:$G$64,"<="&$B$3)) | AE10: =IF($C10="","",SUMIFS(流程1_請假申請!$I$5:$I$64,流程1_請假申請!$D$5:$D$64,$B10,流程1_請假申請!$F$5:$F$64,"育嬰留職停薪",流程1_請假申請!$M$5:$M$64,"已確認",流程1_請假申請!$G$5:$G$64,">="&DATE(YEAR($B$3),1,1),流程1_請假申請!$G$5:$G$64,"<="&$B$3)) | AF10: =IF(C10="","",30-R10) | AG10: =IF(C10="","",14-S10) | AH10: =IF(C10="","",IF(D10="",DATE(YEAR($B$3)+1,1,1),MIN(DATE(YEAR($B$3)+1,1,1),D10+1))) | AI10: =IF(C10="","",MAX(DATE(YEAR($B$3),1,1),MIN(AH10,EDATE(C10,6)))) | AJ10: =IF(C10="","",MAX(AI10,MIN(AH10,EDATE(C10,12*MAX(1,YEAR($B$3)-YEAR(C10)))))) | AK10: =IF(C10="","",IF(IF(DATE(YEAR($B$3),1,1)<$C10,0,DATEDIF($C10,DATE(YEAR($B$3),1,1),"m"))<6,0,IF(IF(DATE(YEAR($B$3),1,1)<$C10,0,DATEDIF($C10,DATE(YEAR($B$3),1,1),"m"))<12,6,IF(IF(DATE(YEAR($B$3),1,1)<$C10,0,DATEDIF($C10,DATE(YEAR($B$3),1,1),"m"))<24,7,IF(IF(DATE(YEAR($B$3),1,1)<$C10,0,DATEDIF($C10,DATE(YEAR($B$3),1,1),"m"))<36,10,IF(IF(DATE(YEAR($B$3),1,1)<$C10,0,DATEDIF($C10,DATE(YEAR($B$3),1,1),"m"))<60,14,IF(IF(DATE(YEAR($B$3),1,1)<$C10,0,DATEDIF($C10,DATE(YEAR($B$3),1,1),"m"))<120,15,MIN(30,15+INT(IF(DATE(YEAR($B$3),1,1)<$C10,0,DATEDIF($C10,DATE(YEAR($B$3),1,1),"m"))/12)-9)))))))) | AL10: =IF(C10="","",IF(IF(AI10<$C10,0,DATEDIF($C10,AI10,"m"))<6,0,IF(IF(AI10<$C10,0,DATEDIF($C10,AI10,"m"))<12,6,IF(IF(AI10<$C10,0,DATEDIF($C10,AI10,"m"))<24,7,IF(IF(AI10<$C10,0,DATEDIF($C10,AI10,"m"))<36,10,IF(IF(AI10<$C10,0,DATEDIF($C10,AI10,"m"))<60,14,IF(IF(AI10<$C10,0,DATEDIF($C10,AI10,"m"))<120,15,MIN(30,15+INT(IF(AI10<$C10,0,DATEDIF($C10,AI10,"m"))/12)-9)))))))) | AM10: =IF(C10="","",IF(IF(AJ10<$C10,0,DATEDIF($C10,AJ10,"m"))<6,0,IF(IF(AJ10<$C10,0,DATEDIF($C10,AJ10,"m"))<12,6,IF(IF(AJ10<$C10,0,DATEDIF($C10,AJ10,"m"))<24,7,IF(IF(AJ10<$C10,0,DATEDIF($C10,AJ10,"m"))<36,10,IF(IF(AJ10<$C10,0,DATEDIF($C10,AJ10,"m"))<60,14,IF(IF(AJ10<$C10,0,DATEDIF($C10,AJ10,"m"))<120,15,MIN(30,15+INT(IF(AJ10<$C10,0,DATEDIF($C10,AJ10,"m"))/12)-9)))))))) | AN10: =IF(C10="","",((AI10-DATE(YEAR($B$3),1,1))*AK10+(AJ10-AI10)*AL10+(AH10-AJ10)*AM10)/(DATE(YEAR($B$3)+1,1,1)-DATE(YEAR($B$3),1,1)))
